Workbook
Name AtividadesDestaque: #REF!
Name DestaquesAFazer: #REF!
Name Redefinir_Área_Impressão: OFFSET(#REF!,0,0,COUNTA(#REF!)+5)
Name SegmentaçãodeDados_Nível: #N/A
Name valInícioD: #REF!
Name valTérminoD: #REF!

Sheet Plano de Trabalho - Baseline
H2: Alvarez & Marsal Infrastructure & Capital Projects
H3: Plano de Trabalho | M3: Data de Atualização: | N3: =TODAY() -> 46164
H5: Cliente: Gerdau
H6: Projeto: Diagnóstico de PAEBM & Implantação GISTM | P6: Data: 22 de Janeiro, de 2024
H7: Setor: Mineração | P7: Revisão: 00 | R7: =DATEVALUE(#REF!) -> #REF! | S7: =DATEVALUE(#REF!) -> #REF! | T7: =DATEVALUE(#REF!) -> #REF! | U7: =DATEVALUE(#REF!) -> #REF! | V7: =DATEVALUE(#REF!) -> #REF! | W7: =DATEVALUE(#REF!) -> #REF! | X7: =DATEVALUE(#REF!) -> #REF! | Y7: =DATEVALUE(#REF!) -> #REF! | ... BM7: =DATEVALUE(#REF!) -> #REF!
B10: Nível | C10: EAP | D10: Nível 1 | E10: Nível 2 | F10: Nível 3 | G10: Nível 4 | H10: Plano de Trabalho - A&M | I10: Data Início Previsto | J10: Data Término Prevista | K10: Data Início Real/Projetado | L10: Data Término Real/Projetado | M10: Responsável | N10: Status | O10: F | P10: Restrições | Q10: Avanço Previsto | R10: Avanço Realizado | S10: 01/02/2025 | T10: 08/02/2025 | U10: 15/02/2025 | V10: 22/02/2025 | W10: 01/03/2025 | X10: 08/03/2025 | Y10: 15/03/2025 | Z10: 22/03/2025 | AA10: 29/03/2025 | AB10: 05/04/2025 | AC10: 12/04/2025 | AD10: 19/04/2025 | AE10: 26/04/2025 | AF10: 03/05/2025 | AG10: 10/05/2025 | AH10: 17/05/2025 | AI10: 24/05/2025 | AJ10: 31/05/2025 | AK10: 07/06/2025 | AL10: 14/06/2025 | AM10: 21/06/2025 | AN10: 28/06/2025 | AO10: 05/07/2025 | AP10: 12/07/2025 | AQ10: 19/07/2025 | AR10: 26/07/2025 | AS10: 02/08/2025 | AT10: 09/08/2025 | AU10: 16/08/2025 | AV10: 23/08/2025 | AW10: 30/08/2025 | AX10: 06/09/2025 | AY10: 13/09/2025 | AZ10: 20/09/2025 | BA10: 27/09/2025 | BB10: 04/10/2025 | BC10: 11/10/2025 | BD10: 18/10/2025 | BE10: 25/10/2025 | BF10: 01/11/2025 | BG10: 08/11/2025 | BH10: 15/11/2025 | BI10: 22/11/2025 | BJ10: 29/11/2025 | BK10: 06/12/2025 | BL10: 13/12/2025 | BM10: 20/12/2025 | BN10: 27/12/2025
B11: {=_xlfn.IFS(LEN(Tab.baseline[[#This Row],[EAP]])=1,"Nível 1",LEN(Tab.baseline[[#This Row],[EAP]])=3,"Nível 2",LEN(Tab.baseline[[#This Row],[EAP]])=5,"Nível 3",LEN(Tab.baseline[[#This Row],[EAP]])=7,"Nível 4",LEN(Tab.baseline[[#This Row],[EAP]])=9,"Nível 5",LEN(Tab.baseline[[#This Row],[EAP]])=11,"Nível 6",LEN(Tab.baseline[[#This Row],[EAP]])=11,"Nível 7")} -> Nível 1 | C11: 1 | D11: - | E11: - | F11: - | G11: - | H11: Arquitetura de projetos GERDAU | I11: =MIN(I12,I18,I140,I45) -> 45689 | J11: =MAX(J12,J18,J140,J45) -> 46014 | K11: =MIN(K12,K18,K140,K45) -> 45689 | L11: =MAX(L12,L18,L140,L45) -> 46014 | N11: {=_xlfn.IFS(L11<$M$3,"Concluído",AND(K11>=$M$3,I11<$M$3,L11>$M$3),"Em andamento",AND(L11>=$M$3,J11<$M$3),"Atrasado",AND(L11>=$M$3,J11>=$M$3,I11>$M$3,K11<=$M$3),"Em andamento",AND(L11>=$M$3,J11>=$M$3,I11<=$M$3,K11<=$M$3),"Em andamento",AND(K11>$M$3,I11>$M$3),"Não iniciado",AND(L11>=$M$3,J11>=$M$3,K11>=$M$3,I11<$M$3),"Atrasado",AND(L11>=$M$3,J11>=$M$3,K11>=$M$3,I11>$M$3),"Não iniciado",AND($I11<=$M$3,$K11>$M$3),"Atrasado")} -> Concluído | O11: {=_xlfn.IFS(N11="Não iniciado",0,N11="Em andamento",1,N11="Concluído",2,N11="Atrasado",3)} -> 2 | Q11: =0.1*Q18+0.75*Q45+0.15*Q140 -> 1 | R11: =0.1*R18+0.75*R45+0.15*R140 -> 1 | S11: =0.1*S18+0.75*S45+0.15*S140 -> #REF! | T11: =0.1*T18+0.75*T45+0.15*T140 -> #REF! | U11: =0.1*U18+0.75*U45+0.15*U140 -> #REF! | V11: =0.1*V18+0.75*V45+0.15*V140 -> #REF! | W11: =0.1*W18+0.75*W45+0.15*W140 -> #REF! | X11: =0.1*X18+0.75*X45+0.15*X140 -> #REF! | ... BN11: =0.1*BN18+0.75*BN45+0.15*BN140 -> #REF!
B12: {=_xlfn.IFS(LEN(Tab.baseline[[#This Row],[EAP]])=1,"Nível 1",LEN(Tab.baseline[[#This Row],[EAP]])=3,"Nível 2",LEN(Tab.baseline[[#This Row],[EAP]])=5,"Nível 3",LEN(Tab.baseline[[#This Row],[EAP]])=7,"Nível 4",LEN(Tab.baseline[[#This Row],[EAP]])=9,"Nível 5",LEN(Tab.baseline[[#This Row],[EAP]])=11,"Nível 6",LEN(Tab.baseline[[#This Row],[EAP]])=11,"Nível 7")} -> Nível 2 | C12: 1.1 | D12: =$H$11 -> Arquitetura de projetos GERDAU | E12: - | F12: - | G12: - | H12: Atividades Preliminares do Projeto | I12: =MIN(I13) -> 45689 | J12: =MAX(J13) -> 45694 | K12: =MIN(K13) -> 45689 | L12: =MAX(L13) -> 45694 | N12: {=_xlfn.IFS(L12<$M$3,"Concluído",AND(K12>=$M$3,I12<$M$3,L12>$M$3),"Em andamento",AND(L12>=$M$3,J12<$M$3),"Atrasado",AND(L12>=$M$3,J12>=$M$3,I12>$M$3,K12<=$M$3),"Em andamento",AND(L12>=$M$3,J12>=$M$3,I12<=$M$3,K12<=$M$3),"Em andamento",AND(K12>$M$3,I12>$M$3),"Não iniciado",AND(L12>=$M$3,J12>=$M$3,K12>=$M$3,I12<$M$3),"Atrasado",AND(L12>=$M$3,J12>=$M$3,K12>=$M$3,I12>$M$3),"Não iniciado",AND($I12<=$M$3,$K12>$M$3),"Atrasado")} -> Concluído | O12: {=_xlfn.IFS(N12="Não iniciado",0,N12="Em andamento",1,N12="Concluído",2,N12="Atrasado",3)} -> 2 | Q12: =Q13 -> 1 | R12: =R13 -> 1 | S12: =S13 -> #REF! | T12: =T13 -> #REF! | U12: =U13 -> #REF! | V12: =V13 -> #REF! | W12: =W13 -> #REF! | X12: =X13 -> #REF! | ... BN12: =BN13 -> #REF!
B13: {=_xlfn.IFS(LEN(Tab.baseline[[#This Row],[EAP]])=1,"Nível 1",LEN(Tab.baseline[[#This Row],[EAP]])=3,"Nível 2",LEN(Tab.baseline[[#This Row],[EAP]])=5,"Nível 3",LEN(Tab.baseline[[#This Row],[EAP]])=7,"Nível 4",LEN(Tab.baseline[[#This Row],[EAP]])=9,"Nível 5",LEN(Tab.baseline[[#This Row],[EAP]])=11,"Nível 6",LEN(Tab.baseline[[#This Row],[EAP]])=11,"Nível 7")} -> Nível 3 | C13: 1.1.1 | D13: =$H$11 -> Arquitetura de projetos GERDAU | E13: Atividades Preliminares do Projeto | F13: - | G13: - | H13: Atividades Preliminares do Projeto | I13: =MIN(I14) -> 45689 | J13: =MAX(J14) -> 45694 | K13: =MIN(K14) -> 45689 | L13: =MAX(L14) -> 45694 | N13: {=_xlfn.IFS(L13<$M$3,"Concluído",AND(K13>=$M$3,I13<$M$3,L13>$M$3),"Em andamento",AND(L13>=$M$3,J13<$M$3),"Atrasado",AND(L13>=$M$3,J13>=$M$3,I13>$M$3,K13<=$M$3),"Em andamento",AND(L13>=$M$3,J13>=$M$3,I13<=$M$3,K13<=$M$3),"Em andamento",AND(K13>$M$3,I13>$M$3),"Não iniciado",AND(L13>=$M$3,J13>=$M$3,K13>=$M$3,I13<$M$3),"Atrasado",AND(L13>=$M$3,J13>=$M$3,K13>=$M$3,I13>$M$3),"Não iniciado",AND($I13<=$M$3,$K13>$M$3),"Atrasado")} -> Concluído | O13: {=_xlfn.IFS(N13="Não iniciado",0,N13="Em andamento",1,N13="Concluído",2,N13="Atrasado",3)} -> 2 | Q13: =Q14 -> 1 | R13: =R14 -> 1 | S13: =S14 -> #REF! | T13: =T14 -> #REF! | U13: =U14 -> #REF! | V13: =V14 -> #REF! | W13: =W14 -> #REF! | X13: =X14 -> #REF! | ... BN13: =BN14 -> #REF!
B14: {=_xlfn.IFS(LEN(Tab.baseline[[#This Row],[EAP]])=1,"Nível 1",LEN(Tab.baseline[[#This Row],[EAP]])=3,"Nível 2",LEN(Tab.baseline[[#This Row],[EAP]])=5,"Nível 3",LEN(Tab.baseline[[#This Row],[EAP]])=7,"Nível 4",LEN(Tab.baseline[[#This Row],[EAP]])=9,"Nível 5",LEN(Tab.baseline[[#This Row],[EAP]])=11,"Nível 6",LEN(Tab.baseline[[#This Row],[EAP]])=11,"Nível 7")} -> Nível 4 | C14: 1.1.1.1 | D14: =$H$11 -> Arquitetura de projetos GERDAU | E14: Atividades Preliminares do Projeto | F14: Atividades Preliminares do Projeto | G14: - | H14: Atividades Preliminares do Projeto | I14: =MIN(I15:I16) -> 45689 | J14: =MAX(J15:J16) -> 45694 | K14: =MIN(K15:K16) -> 45689 | L14: =MAX(L15:L16) -> 45694 | N14: {=_xlfn.IFS(L14<$M$3,"Concluído",AND(K14>=$M$3,I14<$M$3,L14>$M$3),"Em andamento",AND(L14>=$M$3,J14<$M$3),"Atrasado",AND(L14>=$M$3,J14>=$M$3,I14>$M$3,K14<=$M$3),"Em andamento",AND(L14>=$M$3,J14>=$M$3,I14<=$M$3,K14<=$M$3),"Em andamento",AND(K14>$M$3,I14>$M$3),"Não iniciado",AND(L14>=$M$3,J14>=$M$3,K14>=$M$3,I14<$M$3),"Atrasado",AND(L14>=$M$3,J14>=$M$3,K14>=$M$3,I14>$M$3),"Não iniciado",AND($I14<=$M$3,$K14>$M$3),"Atrasado")} -> Concluído | O14: {=_xlfn.IFS(N14="Não iniciado",0,N14="Em andamento",1,N14="Concluído",2,N14="Atrasado",3)} -> 2 | Q14: =AVERAGE(Q15:Q17) -> 1 | R14: =AVERAGE(R15:R17) -> 1 | S14: =AVERAGE(S15:S17) -> #REF! | T14: =AVERAGE(T15:T17) -> #REF! | U14: =AVERAGE(U15:U17) -> #REF! | V14: =AVERAGE(V15:V17) -> #REF! | W14: =AVERAGE(W15:W17) -> #REF! | X14: =AVERAGE(X15:X17) -> #REF! | ... BN14: =AVERAGE(BN15:BN17) -> #REF!
B15: {=_xlfn.IFS(LEN(Tab.baseline[[#This Row],[EAP]])=1,"Nível 1",LEN(Tab.baseline[[#This Row],[EAP]])=3,"Nível 2",LEN(Tab.baseline[[#This Row],[EAP]])=5,"Nível 3",LEN(Tab.baseline[[#This Row],[EAP]])=7,"Nível 4",LEN(Tab.baseline[[#This Row],[EAP]])=9,"Nível 5",LEN(Tab.baseline[[#This Row],[EAP]])=11,"Nível 6",LEN(Tab.baseline[[#This Row],[EAP]])=11,"Nível 7")} -> Nível 5 | C15: 1.1.1.1.1 | D15: =$H$11 -> Arquitetura de projetos GERDAU | E15: Atividades Preliminares do Projeto | F15: Atividades Preliminares do Projeto | G15: Atividades Preliminares do Projeto | H15: Elaboração do Material de KickOff do projeto | I15: 45689 | J15: 45694 | K15: 45689 | L15: 45694 | N15: {=_xlfn.IFS(L15<$M$3,"Concluído",AND(K15>=$M$3,I15<$M$3,L15>$M$3),"Em andamento",AND(L15>=$M$3,J15<$M$3),"Atrasado",AND(L15>=$M$3,J15>=$M$3,I15>$M$3,K15<=$M$3),"Em andamento",AND(L15>=$M$3,J15>=$M$3,I15<=$M$3,K15<=$M$3),"Em andamento",AND(K15>$M$3,I15>$M$3),"Não iniciado",AND(L15>=$M$3,J15>=$M$3,K15>=$M$3,I15<$M$3),"Atrasado",AND(L15>=$M$3,J15>=$M$3,K15>=$M$3,I15>$M$3),"Não iniciado",AND($I15<=$M$3,$K15>$M$3),"Atrasado")} -> Concluído | O15: {=_xlfn.IFS(N15="Não iniciado",0,N15="Em andamento",1,N15="Concluído",2,N15="Atrasado",3)} -> 2 | Q15: {=_xlfn.IFS(AND($I15<$N$3,$J15<$N$3),1,AND($I15<=$N$3,$J15>=$N$3),0.5,AND($I15>=$N$3,$J15>=$N$3),0)} -> 1 | R15: {=_xlfn.IFS(AND($K15<$N$3,$L15<$N$3),1,AND($K15<=$N$3,$L15>=$N$3),0.5,AND($K15>=$N$3,$L15>=$N$3),0)} -> 1 | S15: {=_xlfn.IFS(AND($K15>R$7,$L15>R$7),0,AND($K15<=R$7,$L15<=R$7),1,AND($K15<=R$7,$L15>R$7),((R$7-$K15)/($L15-$K15)))} -> #REF! | T15: {=_xlfn.IFS(AND($K15>S$7,$L15>S$7),0,AND($K15<=S$7,$L15<=S$7),1,AND($K15<=S$7,$L15>S$7),((S$7-$K15)/($L15-$K15)))} -> #REF! | U15: {=_xlfn.IFS(AND($K15>T$7,$L15>T$7),0,AND($K15<=T$7,$L15<=T$7),1,AND($K15<=T$7,$L15>T$7),((T$7-$K15)/($L15-$K15)))} -> #REF! | V15: {=_xlfn.IFS(AND($K15>U$7,$L15>U$7),0,AND($K15<=U$7,$L15<=U$7),1,AND($K15<=U$7,$L15>U$7),((U$7-$K15)/($L15-$K15)))} -> #REF! | W15: {=_xlfn.IFS(AND($K15>V$7,$L15>V$7),0,AND($K15<=V$7,$L15<=V$7),1,AND($K15<=V$7,$L15>V$7),((V$7-$K15)/($L15-$K15)))} -> #REF! | X15: {=_xlfn.IFS(AND($K15>W$7,$L15>W$7),0,AND($K15<=W$7,$L15<=W$7),1,AND($K15<=W$7,$L15>W$7),((W$7-$K15)/($L15-$K15)))} -> #REF! | Y15: {=_xlfn.IFS(AND($K15>X$7,$L15>X$7),0,AND($K15<=X$7,$L15<=X$7),1,AND($K15<=X$7,$L15>X$7),((X$7-$K15)/($L15-$K15)))} -> #REF! | Z15: {=_xlfn.IFS(AND($K15>Y$7,$L15>Y$7),0,AND($K15<=Y$7,$L15<=Y$7),1,AND($K15<=Y$7,$L15>Y$7),((Y$7-$K15)/($L15-$K15)))} -> #REF! | ... BN15: {=_xlfn.IFS(AND($K15>BM$7,$L15>BM$7),0,AND($K15<=BM$7,$L15<=BM$7),1,AND($K15<=BM$7,$L15>BM$7),((BM$7-$K15)/($L15-$K15)))} -> #REF!
B16: {=_xlfn.IFS(LEN(Tab.baseline[[#This Row],[EAP]])=1,"Nível 1",LEN(Tab.baseline[[#This Row],[EAP]])=3,"Nível 2",LEN(Tab.baseline[[#This Row],[EAP]])=5,"Nível 3",LEN(Tab.baseline[[#This Row],[EAP]])=7,"Nível 4",LEN(Tab.baseline[[#This Row],[EAP]])=9,"Nível 5",LEN(Tab.baseline[[#This Row],[EAP]])=11,"Nível 6",LEN(Tab.baseline[[#This Row],[EAP]])=11,"Nível 7")} -> Nível 5 | C16: 1.1.1.2.2 | D16: =$H$11 -> Arquitetura de projetos GERDAU | E16: Atividades Preliminares do Projeto | F16: Atividades Preliminares do Projeto | G16: Atividades Preliminares do Projeto | H16: Realizar Kick-Off do projeto com Sponsor | I16: 45694 | J16: 45694 | K16: 45694 | L16: 45694 | N16: {=_xlfn.IFS(L16<$M$3,"Concluído",AND(K16>=$M$3,I16<$M$3,L16>$M$3),"Em andamento",AND(L16>=$M$3,J16<$M$3),"Atrasado",AND(L16>=$M$3,J16>=$M$3,I16>$M$3,K16<=$M$3),"Em andamento",AND(L16>=$M$3,J16>=$M$3,I16<=$M$3,K16<=$M$3),"Em andamento",AND(K16>$M$3,I16>$M$3),"Não iniciado",AND(L16>=$M$3,J16>=$M$3,K16>=$M$3,I16<$M$3),"Atrasado",AND(L16>=$M$3,J16>=$M$3,K16>=$M$3,I16>$M$3),"Não iniciado",AND($I16<=$M$3,$K16>$M$3),"Atrasado")} -> Concluído | O16: {=_xlfn.IFS(N16="Não iniciado",0,N16="Em andamento",1,N16="Concluído",2,N16="Atrasado",3)} -> 2 | Q16: {=_xlfn.IFS(AND($I16<$N$3,$J16<$N$3),1,AND($I16<=$N$3,$J16>=$N$3),0.5,AND($I16>=$N$3,$J16>=$N$3),0)} -> 1 | R16: {=_xlfn.IFS(AND($K16<$N$3,$L16<$N$3),1,AND($K16<=$N$3,$L16>=$N$3),0.5,AND($K16>=$N$3,$L16>=$N$3),0)} -> 1 | S16: {=_xlfn.IFS(AND($K16>R$7,$L16>R$7),0,AND($K16<=R$7,$L16<=R$7),1,AND($K16<=R$7,$L16>R$7),((R$7-$K16)/($L16-$K16)))} -> #REF! | T16: {=_xlfn.IFS(AND($K16>S$7,$L16>S$7),0,AND($K16<=S$7,$L16<=S$7),1,AND($K16<=S$7,$L16>S$7),((S$7-$K16)/($L16-$K16)))} -> #REF! | U16: {=_xlfn.IFS(AND($K16>T$7,$L16>T$7),0,AND($K16<=T$7,$L16<=T$7),1,AND($K16<=T$7,$L16>T$7),((T$7-$K16)/($L16-$K16)))} -> #REF! | V16: {=_xlfn.IFS(AND($K16>U$7,$L16>U$7),0,AND($K16<=U$7,$L16<=U$7),1,AND($K16<=U$7,$L16>U$7),((U$7-$K16)/($L16-$K16)))} -> #REF! | W16: {=_xlfn.IFS(AND($K16>V$7,$L16>V$7),0,AND($K16<=V$7,$L16<=V$7),1,AND($K16<=V$7,$L16>V$7),((V$7-$K16)/($L16-$K16)))} -> #REF! | X16: {=_xlfn.IFS(AND($K16>W$7,$L16>W$7),0,AND($K16<=W$7,$L16<=W$7),1,AND($K16<=W$7,$L16>W$7),((W$7-$K16)/($L16-$K16)))} -> #REF! | Y16: {=_xlfn.IFS(AND($K16>X$7,$L16>X$7),0,AND($K16<=X$7,$L16<=X$7),1,AND($K16<=X$7,$L16>X$7),((X$7-$K16)/($L16-$K16)))} -> #REF! | Z16: {=_xlfn.IFS(AND($K16>Y$7,$L16>Y$7),0,AND($K16<=Y$7,$L16<=Y$7),1,AND($K16<=Y$7,$L16>Y$7),((Y$7-$K16)/($L16-$K16)))} -> #REF! | ... BN16: {=_xlfn.IFS(AND($K16>BM$7,$L16>BM$7),0,AND($K16<=BM$7,$L16<=BM$7),1,AND($K16<=BM$7,$L16>BM$7),((BM$7-$K16)/($L16-$K16)))} -> #REF!
B17: {=_xlfn.IFS(LEN(Tab.baseline[[#This Row],[EAP]])=1,"Nível 1",LEN(Tab.baseline[[#This Row],[EAP]])=3,"Nível 2",LEN(Tab.baseline[[#This Row],[EAP]])=5,"Nível 3",LEN(Tab.baseline[[#This Row],[EAP]])=7,"Nível 4",LEN(Tab.baseline[[#This Row],[EAP]])=9,"Nível 5",LEN(Tab.baseline[[#This Row],[EAP]])=11,"Nível 6",LEN(Tab.baseline[[#This Row],[EAP]])=11,"Nível 7")} -> Nível 5 | C17: 1.1.1.2.3 | D17: =$H$11 -> Arquitetura de projetos GERDAU | E17: Atividades Preliminares do Projeto | F17: Atividades Preliminares do Projeto | G17: Atividades Preliminares do Projeto | H17: Realização do PIM para mobilização | I17: 45700 | J17: 45702 | K17: 45700 | L17: 45702 | N17: {=_xlfn.IFS(L17<$M$3,"Concluído",AND(K17>=$M$3,I17<$M$3,L17>$M$3),"Em andamento",AND(L17>=$M$3,J17<$M$3),"Atrasado",AND(L17>=$M$3,J17>=$M$3,I17>$M$3,K17<=$M$3),"Em andamento",AND(L17>=$M$3,J17>=$M$3,I17<=$M$3,K17<=$M$3),"Em andamento",AND(K17>$M$3,I17>$M$3),"Não iniciado",AND(L17>=$M$3,J17>=$M$3,K17>=$M$3,I17<$M$3),"Atrasado",AND(L17>=$M$3,J17>=$M$3,K17>=$M$3,I17>$M$3),"Não iniciado",AND($I17<=$M$3,$K17>$M$3),"Atrasado")} -> Concluído | O17: {=_xlfn.IFS(N17="Não iniciado",0,N17="Em andamento",1,N17="Concluído",2,N17="Atrasado",3)} -> 2 | Q17: {=_xlfn.IFS(AND($I17<$N$3,$J17<$N$3),1,AND($I17<=$N$3,$J17>=$N$3),0.5,AND($I17>=$N$3,$J17>=$N$3),0)} -> 1 | R17: {=_xlfn.IFS(AND($K17<$N$3,$L17<$N$3),1,AND($K17<=$N$3,$L17>=$N$3),0.5,AND($K17>=$N$3,$L17>=$N$3),0)} -> 1 | S17: {=_xlfn.IFS(AND($K17>R$7,$L17>R$7),0,AND($K17<=R$7,$L17<=R$7),1,AND($K17<=R$7,$L17>R$7),((R$7-$K17)/($L17-$K17)))} -> #REF! | T17: {=_xlfn.IFS(AND($K17>S$7,$L17>S$7),0,AND($K17<=S$7,$L17<=S$7),1,AND($K17<=S$7,$L17>S$7),((S$7-$K17)/($L17-$K17)))} -> #REF! | U17: {=_xlfn.IFS(AND($K17>T$7,$L17>T$7),0,AND($K17<=T$7,$L17<=T$7),1,AND($K17<=T$7,$L17>T$7),((T$7-$K17)/($L17-$K17)))} -> #REF! | V17: {=_xlfn.IFS(AND($K17>U$7,$L17>U$7),0,AND($K17<=U$7,$L17<=U$7),1,AND($K17<=U$7,$L17>U$7),((U$7-$K17)/($L17-$K17)))} -> #REF! | W17: {=_xlfn.IFS(AND($K17>V$7,$L17>V$7),0,AND($K17<=V$7,$L17<=V$7),1,AND($K17<=V$7,$L17>V$7),((V$7-$K17)/($L17-$K17)))} -> #REF! | X17: {=_xlfn.IFS(AND($K17>W$7,$L17>W$7),0,AND($K17<=W$7,$L17<=W$7),1,AND($K17<=W$7,$L17>W$7),((W$7-$K17)/($L17-$K17)))} -> #REF! | Y17: {=_xlfn.IFS(AND($K17>X$7,$L17>X$7),0,AND($K17<=X$7,$L17<=X$7),1,AND($K17<=X$7,$L17>X$7),((X$7-$K17)/($L17-$K17)))} -> #REF! | Z17: {=_xlfn.IFS(AND($K17>Y$7,$L17>Y$7),0,AND($K17<=Y$7,$L17<=Y$7),1,AND($K17<=Y$7,$L17>Y$7),((Y$7-$K17)/($L17-$K17)))} -> #REF! | ... BN17: {=_xlfn.IFS(AND($K17>BM$7,$L17>BM$7),0,AND($K17<=BM$7,$L17<=BM$7),1,AND($K17<=BM$7,$L17>BM$7),((BM$7-$K17)/($L17-$K17)))} -> #REF!
B18: {=_xlfn.IFS(LEN(Tab.baseline[[#This Row],[EAP]])=1,"Nível 1",LEN(Tab.baseline[[#This Row],[EAP]])=3,"Nível 2",LEN(Tab.baseline[[#This Row],[EAP]])=5,"Nível 3",LEN(Tab.baseline[[#This Row],[EAP]])=7,"Nível 4",LEN(Tab.baseline[[#This Row],[EAP]])=9,"Nível 5",LEN(Tab.baseline[[#This Row],[EAP]])=11,"Nível 6",LEN(Tab.baseline[[#This Row],[EAP]])=11,"Nível 7")} -> Nível 2 | C18: 1.2 | D18: =$H$11 -> Arquitetura de projetos GERDAU | E18: - | F18: - | G18: - | H18: Definição da Estratégia para Transformação dos Processos | I18: =MIN(I19,I26,I40) -> 45705 | J18: =MIN(J19,J26,J40) -> 45715 | K18: =MIN(K19,K26,K40) -> 45705 | L18: =MIN(L19,L26,L40) -> 45715 | N18: {=_xlfn.IFS(L18<$M$3,"Concluído",AND(K18>=$M$3,I18<$M$3,L18>$M$3),"Em andamento",AND(L18>=$M$3,J18<$M$3),"Atrasado",AND(L18>=$M$3,J18>=$M$3,I18>$M$3,K18<=$M$3),"Em andamento",AND(L18>=$M$3,J18>=$M$3,I18<=$M$3,K18<=$M$3),"Em andamento",AND(K18>$M$3,I18>$M$3),"Não iniciado",AND(L18>=$M$3,J18>=$M$3,K18>=$M$3,I18<$M$3),"Atrasado",AND(L18>=$M$3,J18>=$M$3,K18>=$M$3,I18>$M$3),"Não iniciado",AND($I18<=$M$3,$K18>$M$3),"Atrasado")} -> Concluído | O18: {=_xlfn.IFS(N18="Não iniciado",0,N18="Em andamento",1,N18="Concluído",2,N18="Atrasado",3)} -> 2 | Q18: =AVERAGE(Q19,Q26,Q40) -> 1 | R18: =AVERAGE(R19,R26,R40) -> 1 | S18: =AVERAGE(S19,S26,S40) -> #REF! | T18: =AVERAGE(T19,T26,T40) -> #REF! | U18: =AVERAGE(U19,U26,U40) -> #REF! | V18: =AVERAGE(V19,V26,V40) -> #REF! | W18: =AVERAGE(W19,W26,W40) -> #REF! | X18: =AVERAGE(X19,X26,X40) -> #REF! | ... BN18: =AVERAGE(BN19,BN26,BN40) -> #REF!
B19: {=_xlfn.IFS(LEN(Tab.baseline[[#This Row],[EAP]])=1,"Nível 1",LEN(Tab.baseline[[#This Row],[EAP]])=3,"Nível 2",LEN(Tab.baseline[[#This Row],[EAP]])=5,"Nível 3",LEN(Tab.baseline[[#This Row],[EAP]])=7,"Nível 4",LEN(Tab.baseline[[#This Row],[EAP]])=9,"Nível 5",LEN(Tab.baseline[[#This Row],[EAP]])=11,"Nível 6",LEN(Tab.baseline[[#This Row],[EAP]])=11,"Nível 7")} -> Nível 3 | C19: 1.2.1 | D19: =$H$11 -> Arquitetura de projetos GERDAU | E19: =$H$18 -> Definição da Estratégia para Transformação dos Processos | F19: - | G19: - | H19: Revisão dos Objetivos Estratégicos e Cadeia de Valor | I19: =MIN(I21:I21) -> 45705 | J19: =MAX(J21:J21) -> 45715 | K19: =MIN(K21:K21) -> 45705 | L19: =MAX(L21:L21) -> 45715 | N19: {=_xlfn.IFS(L19<$M$3,"Concluído",AND(K19>=$M$3,I19<$M$3,L19>$M$3),"Em andamento",AND(L19>=$M$3,J19<$M$3),"Atrasado",AND(L19>=$M$3,J19>=$M$3,I19>$M$3,K19<=$M$3),"Em andamento",AND(L19>=$M$3,J19>=$M$3,I19<=$M$3,K19<=$M$3),"Em andamento",AND(K19>$M$3,I19>$M$3),"Não iniciado",AND(L19>=$M$3,J19>=$M$3,K19>=$M$3,I19<$M$3),"Atrasado",AND(L19>=$M$3,J19>=$M$3,K19>=$M$3,I19>$M$3),"Não iniciado",AND($I19<=$M$3,$K19>$M$3),"Atrasado")} -> Concluído | O19: {=_xlfn.IFS(N19="Não iniciado",0,N19="Em andamento",1,N19="Concluído",2,N19="Atrasado",3)} -> 2 | Q19: =AVERAGE(Q20,Q22,Q24) -> 1 | R19: =AVERAGE(R20,R22,R24) -> 1 | S19: =AVERAGE(S20,S22,S24) -> #REF! | T19: =AVERAGE(T20,T22,T24) -> #REF! | U19: =AVERAGE(U20,U22,U24) -> #REF! | V19: =AVERAGE(V20,V22,V24) -> #REF! | W19: =AVERAGE(W20,W22,W24) -> #REF! | X19: =AVERAGE(X20,X22,X24) -> #REF! | ... BN19: =AVERAGE(BN20,BN22,BN24) -> #REF!
B20: {=_xlfn.IFS(LEN(Tab.baseline[[#This Row],[EAP]])=1,"Nível 1",LEN(Tab.baseline[[#This Row],[EAP]])=3,"Nível 2",LEN(Tab.baseline[[#This Row],[EAP]])=5,"Nível 3",LEN(Tab.baseline[[#This Row],[EAP]])=7,"Nível 4",LEN(Tab.baseline[[#This Row],[EAP]])=9,"Nível 5",LEN(Tab.baseline[[#This Row],[EAP]])=11,"Nível 6",LEN(Tab.baseline[[#This Row],[EAP]])=11,"Nível 7")} -> Nível 4 | C20: 1.2.1.1 | D20: =$H$11 -> Arquitetura de projetos GERDAU | E20: =$H$18 -> Definição da Estratégia para Transformação dos Processos | F20: =$H$19 -> Revisão dos Objetivos Estratégicos e Cadeia de Valor | G20: - | H20: Revisão dos objetivos estratégicos da Gerência | I20: =MIN(I21:I21) -> 45705 | J20: =MAX(J21:J21) -> 45715 | K20: =MIN(K21:K21) -> 45705 | L20: =MAX(L21:L21) -> 45715 | N20: {=_xlfn.IFS(L20<$M$3,"Concluído",AND(K20>=$M$3,I20<$M$3,L20>$M$3),"Em andamento",AND(L20>=$M$3,J20<$M$3),"Atrasado",AND(L20>=$M$3,J20>=$M$3,I20>$M$3,K20<=$M$3),"Em andamento",AND(L20>=$M$3,J20>=$M$3,I20<=$M$3,K20<=$M$3),"Em andamento",AND(K20>$M$3,I20>$M$3),"Não iniciado",AND(L20>=$M$3,J20>=$M$3,K20>=$M$3,I20<$M$3),"Atrasado",AND(L20>=$M$3,J20>=$M$3,K20>=$M$3,I20>$M$3),"Não iniciado",AND($I20<=$M$3,$K20>$M$3),"Atrasado")} -> Concluído | O20: {=_xlfn.IFS(N20="Não iniciado",0,N20="Em andamento",1,N20="Concluído",2,N20="Atrasado",3)} -> 2 | Q20: =AVERAGE(Q21:Q21) -> 1 | R20: =AVERAGE(R21:R21) -> 1 | S20: =S21 -> #REF! | T20: =T21 -> #REF! | U20: =U21 -> #REF! | V20: =V21 -> #REF! | W20: =W21 -> #REF! | X20: =X21 -> #REF! | Y20: =Y21 -> #REF! | Z20: =Z21 -> #REF! | ... BN20: =BN21 -> #REF!
B21: {=_xlfn.IFS(LEN(Tab.baseline[[#This Row],[EAP]])=1,"Nível 1",LEN(Tab.baseline[[#This Row],[EAP]])=3,"Nível 2",LEN(Tab.baseline[[#This Row],[EAP]])=5,"Nível 3",LEN(Tab.baseline[[#This Row],[EAP]])=7,"Nível 4",LEN(Tab.baseline[[#This Row],[EAP]])=9,"Nível 5",LEN(Tab.baseline[[#This Row],[EAP]])=11,"Nível 6",LEN(Tab.baseline[[#This Row],[EAP]])=11,"Nível 7")} -> Nível 5 | C21: 1.2.1.1.1 | D21: =$H$11 -> Arquitetura de projetos GERDAU | E21: =$H$18 -> Definição da Estratégia para Transformação dos Processos | F21: =$H$19 -> Revisão dos Objetivos Estratégicos e Cadeia de Valor | G21: =H20 -> Revisão dos objetivos estratégicos da Gerência | H21: Revisão dos objetivos estratégicos da Gerência | I21: 45705 | J21: 45715 | K21: 45705 | L21: 45715 | N21: {=_xlfn.IFS(L21<$M$3,"Concluído",AND(K21>=$M$3,I21<$M$3,L21>$M$3),"Em andamento",AND(L21>=$M$3,J21<$M$3),"Atrasado",AND(L21>=$M$3,J21>=$M$3,I21>$M$3,K21<=$M$3),"Em andamento",AND(L21>=$M$3,J21>=$M$3,I21<=$M$3,K21<=$M$3),"Em andamento",AND(K21>$M$3,I21>$M$3),"Não iniciado",AND(L21>=$M$3,J21>=$M$3,K21>=$M$3,I21<$M$3),"Atrasado",AND(L21>=$M$3,J21>=$M$3,K21>=$M$3,I21>$M$3),"Não iniciado",AND($I21<=$M$3,$K21>$M$3),"Atrasado")} -> Concluído | O21: {=_xlfn.IFS(N21="Não iniciado",0,N21="Em andamento",1,N21="Concluído",2,N21="Atrasado",3)} -> 2 | Q21: {=_xlfn.IFS(AND($I21<$N$3,$J21<$N$3),1,AND($I21<=$N$3,$J21>=$N$3),0.5,AND($I21>=$N$3,$J21>=$N$3),0)} -> 1 | R21: {=_xlfn.IFS(AND($K21<$N$3,$L21<$N$3),1,AND($K21<=$N$3,$L21>=$N$3),0.5,AND($K21>=$N$3,$L21>=$N$3),0)} -> 1 | S21: {=_xlfn.IFS(AND($K21>R$7,$L21>R$7),0,AND($K21<=R$7,$L21<=R$7),1,AND($K21<=R$7,$L21>R$7),((R$7-$K21)/($L21-$K21)))} -> #REF! | T21: {=_xlfn.IFS(AND($K21>S$7,$L21>S$7),0,AND($K21<=S$7,$L21<=S$7),1,AND($K21<=S$7,$L21>S$7),((S$7-$K21)/($L21-$K21)))} -> #REF! | U21: {=_xlfn.IFS(AND($K21>T$7,$L21>T$7),0,AND($K21<=T$7,$L21<=T$7),1,AND($K21<=T$7,$L21>T$7),((T$7-$K21)/($L21-$K21)))} -> #REF! | V21: {=_xlfn.IFS(AND($K21>U$7,$L21>U$7),0,AND($K21<=U$7,$L21<=U$7),1,AND($K21<=U$7,$L21>U$7),((U$7-$K21)/($L21-$K21)))} -> #REF! | W21: {=_xlfn.IFS(AND($K21>V$7,$L21>V$7),0,AND($K21<=V$7,$L21<=V$7),1,AND($K21<=V$7,$L21>V$7),((V$7-$K21)/($L21-$K21)))} -> #REF! | X21: {=_xlfn.IFS(AND($K21>W$7,$L21>W$7),0,AND($K21<=W$7,$L21<=W$7),1,AND($K21<=W$7,$L21>W$7),((W$7-$K21)/($L21-$K21)))} -> #REF! | Y21: {=_xlfn.IFS(AND($K21>X$7,$L21>X$7),0,AND($K21<=X$7,$L21<=X$7),1,AND($K21<=X$7,$L21>X$7),((X$7-$K21)/($L21-$K21)))} -> #REF! | Z21: {=_xlfn.IFS(AND($K21>Y$7,$L21>Y$7),0,AND($K21<=Y$7,$L21<=Y$7),1,AND($K21<=Y$7,$L21>Y$7),((Y$7-$K21)/($L21-$K21)))} -> #REF! | ... BN21: {=_xlfn.IFS(AND($K21>BM$7,$L21>BM$7),0,AND($K21<=BM$7,$L21<=BM$7),1,AND($K21<=BM$7,$L21>BM$7),((BM$7-$K21)/($L21-$K21)))} -> #REF!
B22: {=_xlfn.IFS(LEN(Tab.baseline[[#This Row],[EAP]])=1,"Nível 1",LEN(Tab.baseline[[#This Row],[EAP]])=3,"Nível 2",LEN(Tab.baseline[[#This Row],[EAP]])=5,"Nível 3",LEN(Tab.baseline[[#This Row],[EAP]])=7,"Nível 4",LEN(Tab.baseline[[#This Row],[EAP]])=9,"Nível 5",LEN(Tab.baseline[[#This Row],[EAP]])=11,"Nível 6",LEN(Tab.baseline[[#This Row],[EAP]])=11,"Nível 7")} -> Nível 4 | C22: 1.2.1.2 | D22: =$H$11 -> Arquitetura de projetos GERDAU | E22: =$H$18 -> Definição da Estratégia para Transformação dos Processos | F22: =$H$19 -> Revisão dos Objetivos Estratégicos e Cadeia de Valor | G22: Atividades Preliminares da Frente | H22: Revisão da cadeia de valor dos processos | I22: =MIN(I23:I23) -> 45705 | J22: =MAX(J23:J23) -> 45715 | K22: =MIN(K23:K23) -> 45705 | L22: =MAX(L23:L23) -> 45715 | N22: {=_xlfn.IFS(L22<$M$3,"Concluído",AND(K22>=$M$3,I22<$M$3,L22>$M$3),"Em andamento",AND(L22>=$M$3,J22<$M$3),"Atrasado",AND(L22>=$M$3,J22>=$M$3,I22>$M$3,K22<=$M$3),"Em andamento",AND(L22>=$M$3,J22>=$M$3,I22<=$M$3,K22<=$M$3),"Em andamento",AND(K22>$M$3,I22>$M$3),"Não iniciado",AND(L22>=$M$3,J22>=$M$3,K22>=$M$3,I22<$M$3),"Atrasado",AND(L22>=$M$3,J22>=$M$3,K22>=$M$3,I22>$M$3),"Não iniciado",AND($I22<=$M$3,$K22>$M$3),"Atrasado")} -> Concluído | O22: {=_xlfn.IFS(N22="Não iniciado",0,N22="Em andamento",1,N22="Concluído",2,N22="Atrasado",3)} -> 2 | Q22: =Q23 -> 1 | R22: =R23 -> 1 | S22: =S23 -> #REF! | T22: =T23 -> #REF! | U22: =U23 -> #REF! | V22: =V23 -> #REF! | W22: =W23 -> #REF! | X22: =X23 -> #REF! | ... BN22: =BN23 -> #REF!
B23: {=_xlfn.IFS(LEN(Tab.baseline[[#This Row],[EAP]])=1,"Nível 1",LEN(Tab.baseline[[#This Row],[EAP]])=3,"Nível 2",LEN(Tab.baseline[[#This Row],[EAP]])=5,"Nível 3",LEN(Tab.baseline[[#This Row],[EAP]])=7,"Nível 4",LEN(Tab.baseline[[#This Row],[EAP]])=9,"Nível 5",LEN(Tab.baseline[[#This Row],[EAP]])=11,"Nível 6",LEN(Tab.baseline[[#This Row],[EAP]])=11,"Nível 7")} -> Nível 5 | C23: 1.2.1.2.1 | D23: =$H$11 -> Arquitetura de projetos GERDAU | E23: =$H$18 -> Definição da Estratégia para Transformação dos Processos | F23: =$H$19 -> Revisão dos Objetivos Estratégicos e Cadeia de Valor | G23: =H22 -> Revisão da cadeia de valor dos processos | H23: Revisão da cadeia de valor dos processos | I23: 45705 | J23: 45715 | K23: 45705 | L23: 45715 | N23: {=_xlfn.IFS(L23<$M$3,"Concluído",AND(K23>=$M$3,I23<$M$3,L23>$M$3),"Em andamento",AND(L23>=$M$3,J23<$M$3),"Atrasado",AND(L23>=$M$3,J23>=$M$3,I23>$M$3,K23<=$M$3),"Em andamento",AND(L23>=$M$3,J23>=$M$3,I23<=$M$3,K23<=$M$3),"Em andamento",AND(K23>$M$3,I23>$M$3),"Não iniciado",AND(L23>=$M$3,J23>=$M$3,K23>=$M$3,I23<$M$3),"Atrasado",AND(L23>=$M$3,J23>=$M$3,K23>=$M$3,I23>$M$3),"Não iniciado",AND($I23<=$M$3,$K23>$M$3),"Atrasado")} -> Concluído | O23: {=_xlfn.IFS(N23="Não iniciado",0,N23="Em andamento",1,N23="Concluído",2,N23="Atrasado",3)} -> 2 | Q23: {=_xlfn.IFS(AND($I23<$N$3,$J23<$N$3),1,AND($I23<=$N$3,$J23>=$N$3),0.5,AND($I23>=$N$3,$J23>=$N$3),0)} -> 1 | R23: {=_xlfn.IFS(AND($K23<$N$3,$L23<$N$3),1,AND($K23<=$N$3,$L23>=$N$3),0.5,AND($K23>=$N$3,$L23>=$N$3),0)} -> 1 | S23: {=_xlfn.IFS(AND($K23>R$7,$L23>R$7),0,AND($K23<=R$7,$L23<=R$7),1,AND($K23<=R$7,$L23>R$7),((R$7-$K23)/($L23-$K23)))} -> #REF! | T23: {=_xlfn.IFS(AND($K23>S$7,$L23>S$7),0,AND($K23<=S$7,$L23<=S$7),1,AND($K23<=S$7,$L23>S$7),((S$7-$K23)/($L23-$K23)))} -> #REF! | U23: {=_xlfn.IFS(AND($K23>T$7,$L23>T$7),0,AND($K23<=T$7,$L23<=T$7),1,AND($K23<=T$7,$L23>T$7),((T$7-$K23)/($L23-$K23)))} -> #REF! | V23: {=_xlfn.IFS(AND($K23>U$7,$L23>U$7),0,AND($K23<=U$7,$L23<=U$7),1,AND($K23<=U$7,$L23>U$7),((U$7-$K23)/($L23-$K23)))} -> #REF! | W23: {=_xlfn.IFS(AND($K23>V$7,$L23>V$7),0,AND($K23<=V$7,$L23<=V$7),1,AND($K23<=V$7,$L23>V$7),((V$7-$K23)/($L23-$K23)))} -> #REF! | X23: {=_xlfn.IFS(AND($K23>W$7,$L23>W$7),0,AND($K23<=W$7,$L23<=W$7),1,AND($K23<=W$7,$L23>W$7),((W$7-$K23)/($L23-$K23)))} -> #REF! | Y23: {=_xlfn.IFS(AND($K23>X$7,$L23>X$7),0,AND($K23<=X$7,$L23<=X$7),1,AND($K23<=X$7,$L23>X$7),((X$7-$K23)/($L23-$K23)))} -> #REF! | Z23: {=_xlfn.IFS(AND($K23>Y$7,$L23>Y$7),0,AND($K23<=Y$7,$L23<=Y$7),1,AND($K23<=Y$7,$L23>Y$7),((Y$7-$K23)/($L23-$K23)))} -> #REF! | ... BN23: {=_xlfn.IFS(AND($K23>BM$7,$L23>BM$7),0,AND($K23<=BM$7,$L23<=BM$7),1,AND($K23<=BM$7,$L23>BM$7),((BM$7-$K23)/($L23-$K23)))} -> #REF!
B24: {=_xlfn.IFS(LEN(Tab.baseline[[#This Row],[EAP]])=1,"Nível 1",LEN(Tab.baseline[[#This Row],[EAP]])=3,"Nível 2",LEN(Tab.baseline[[#This Row],[EAP]])=5,"Nível 3",LEN(Tab.baseline[[#This Row],[EAP]])=7,"Nível 4",LEN(Tab.baseline[[#This Row],[EAP]])=9,"Nível 5",LEN(Tab.baseline[[#This Row],[EAP]])=11,"Nível 6",LEN(Tab.baseline[[#This Row],[EAP]])=11,"Nível 7")} -> Nível 4 | C24: 1.2.1.3 | D24: =$H$11 -> Arquitetura de projetos GERDAU | E24: =$H$18 -> Definição da Estratégia para Transformação dos Processos | F24: =$H$19 -> Revisão dos Objetivos Estratégicos e Cadeia de Valor | G24: Atividades Preliminares da Frente | H24: Definição dos principais direcionadores estratégicos para transformação de processos | I24: =MIN(I25:I25) -> 45705 | J24: =MAX(J25:J25) -> 45708 | K24: =MIN(K25:K25) -> 45705 | L24: =MAX(L25:L25) -> 45708 | N24: {=_xlfn.IFS(L24<$M$3,"Concluído",AND(K24>=$M$3,I24<$M$3,L24>$M$3),"Em andamento",AND(L24>=$M$3,J24<$M$3),"Atrasado",AND(L24>=$M$3,J24>=$M$3,I24>$M$3,K24<=$M$3),"Em andamento",AND(L24>=$M$3,J24>=$M$3,I24<=$M$3,K24<=$M$3),"Em andamento",AND(K24>$M$3,I24>$M$3),"Não iniciado",AND(L24>=$M$3,J24>=$M$3,K24>=$M$3,I24<$M$3),"Atrasado",AND(L24>=$M$3,J24>=$M$3,K24>=$M$3,I24>$M$3),"Não iniciado",AND($I24<=$M$3,$K24>$M$3),"Atrasado")} -> Concluído | O24: {=_xlfn.IFS(N24="Não iniciado",0,N24="Em andamento",1,N24="Concluído",2,N24="Atrasado",3)} -> 2 | Q24: =Q25 -> 1 | R24: =R25 -> 1 | S24: =S25 -> #REF! | T24: =T25 -> #REF! | U24: =U25 -> #REF! | V24: =V25 -> #REF! | W24: =W25 -> #REF! | X24: =X25 -> #REF! | ... BN24: =BN25 -> #REF!
B25: {=_xlfn.IFS(LEN(Tab.baseline[[#This Row],[EAP]])=1,"Nível 1",LEN(Tab.baseline[[#This Row],[EAP]])=3,"Nível 2",LEN(Tab.baseline[[#This Row],[EAP]])=5,"Nível 3",LEN(Tab.baseline[[#This Row],[EAP]])=7,"Nível 4",LEN(Tab.baseline[[#This Row],[EAP]])=9,"Nível 5",LEN(Tab.baseline[[#This Row],[EAP]])=11,"Nível 6",LEN(Tab.baseline[[#This Row],[EAP]])=11,"Nível 7")} -> Nível 5 | C25: 1.2.1.3.1 | D25: =$H$11 -> Arquitetura de projetos GERDAU | E25: =$H$18 -> Definição da Estratégia para Transformação dos Processos | F25: =$H$19 -> Revisão dos Objetivos Estratégicos e Cadeia de Valor | G25: =H24 -> Definição dos principais direcionadores estratégicos para transformação de processos | H25: Definição dos principais direcionadores estratégicos para transformação de processos | I25: 45705 | J25: 45708 | K25: 45705 | L25: 45708 | N25: {=_xlfn.IFS(L25<$M$3,"Concluído",AND(K25>=$M$3,I25<$M$3,L25>$M$3),"Em andamento",AND(L25>=$M$3,J25<$M$3),"Atrasado",AND(L25>=$M$3,J25>=$M$3,I25>$M$3,K25<=$M$3),"Em andamento",AND(L25>=$M$3,J25>=$M$3,I25<=$M$3,K25<=$M$3),"Em andamento",AND(K25>$M$3,I25>$M$3),"Não iniciado",AND(L25>=$M$3,J25>=$M$3,K25>=$M$3,I25<$M$3),"Atrasado",AND(L25>=$M$3,J25>=$M$3,K25>=$M$3,I25>$M$3),"Não iniciado",AND($I25<=$M$3,$K25>$M$3),"Atrasado")} -> Concluído | O25: {=_xlfn.IFS(N25="Não iniciado",0,N25="Em andamento",1,N25="Concluído",2,N25="Atrasado",3)} -> 2 | Q25: {=_xlfn.IFS(AND($I25<$N$3,$J25<$N$3),1,AND($I25<=$N$3,$J25>=$N$3),0.5,AND($I25>=$N$3,$J25>=$N$3),0)} -> 1 | R25: {=_xlfn.IFS(AND($K25<$N$3,$L25<$N$3),1,AND($K25<=$N$3,$L25>=$N$3),0.5,AND($K25>=$N$3,$L25>=$N$3),0)} -> 1 | S25: {=_xlfn.IFS(AND($K25>R$7,$L25>R$7),0,AND($K25<=R$7,$L25<=R$7),1,AND($K25<=R$7,$L25>R$7),((R$7-$K25)/($L25-$K25)))} -> #REF! | T25: {=_xlfn.IFS(AND($K25>S$7,$L25>S$7),0,AND($K25<=S$7,$L25<=S$7),1,AND($K25<=S$7,$L25>S$7),((S$7-$K25)/($L25-$K25)))} -> #REF! | U25: {=_xlfn.IFS(AND($K25>T$7,$L25>T$7),0,AND($K25<=T$7,$L25<=T$7),1,AND($K25<=T$7,$L25>T$7),((T$7-$K25)/($L25-$K25)))} -> #REF! | V25: {=_xlfn.IFS(AND($K25>U$7,$L25>U$7),0,AND($K25<=U$7,$L25<=U$7),1,AND($K25<=U$7,$L25>U$7),((U$7-$K25)/($L25-$K25)))} -> #REF! | W25: {=_xlfn.IFS(AND($K25>V$7,$L25>V$7),0,AND($K25<=V$7,$L25<=V$7),1,AND($K25<=V$7,$L25>V$7),((V$7-$K25)/($L25-$K25)))} -> #REF! | X25: {=_xlfn.IFS(AND($K25>W$7,$L25>W$7),0,AND($K25<=W$7,$L25<=W$7),1,AND($K25<=W$7,$L25>W$7),((W$7-$K25)/($L25-$K25)))} -> #REF! | Y25: {=_xlfn.IFS(AND($K25>X$7,$L25>X$7),0,AND($K25<=X$7,$L25<=X$7),1,AND($K25<=X$7,$L25>X$7),((X$7-$K25)/($L25-$K25)))} -> #REF! | Z25: {=_xlfn.IFS(AND($K25>Y$7,$L25>Y$7),0,AND($K25<=Y$7,$L25<=Y$7),1,AND($K25<=Y$7,$L25>Y$7),((Y$7-$K25)/($L25-$K25)))} -> #REF! | ... BN25: {=_xlfn.IFS(AND($K25>BM$7,$L25>BM$7),0,AND($K25<=BM$7,$L25<=BM$7),1,AND($K25<=BM$7,$L25>BM$7),((BM$7-$K25)/($L25-$K25)))} -> #REF!
B26: {=_xlfn.IFS(LEN(Tab.baseline[[#This Row],[EAP]])=1,"Nível 1",LEN(Tab.baseline[[#This Row],[EAP]])=3,"Nível 2",LEN(Tab.baseline[[#This Row],[EAP]])=5,"Nível 3",LEN(Tab.baseline[[#This Row],[EAP]])=7,"Nível 4",LEN(Tab.baseline[[#This Row],[EAP]])=9,"Nível 5",LEN(Tab.baseline[[#This Row],[EAP]])=11,"Nível 6",LEN(Tab.baseline[[#This Row],[EAP]])=11,"Nível 7")} -> Nível 3 | C26: 1.2.2 | D26: =$H$11 -> Arquitetura de projetos GERDAU | E26: =$H$18 -> Definição da Estratégia para Transformação dos Processos | F26: - | G26: - | H26: Entendimento Inicial dos Processos | I26: =MIN(I27:I44) -> 45705 | J26: =MAX(J27:J44) -> 45729 | K26: =MIN(K27:K44) -> 45705 | L26: =MAX(L27:L44) -> 45727 | N26: {=_xlfn.IFS(L26<$M$3,"Concluído",AND(K26>=$M$3,I26<$M$3,L26>$M$3),"Em andamento",AND(L26>=$M$3,J26<$M$3),"Atrasado",AND(L26>=$M$3,J26>=$M$3,I26>$M$3,K26<=$M$3),"Em andamento",AND(L26>=$M$3,J26>=$M$3,I26<=$M$3,K26<=$M$3),"Em andamento",AND(K26>$M$3,I26>$M$3),"Não iniciado",AND(L26>=$M$3,J26>=$M$3,K26>=$M$3,I26<$M$3),"Atrasado",AND(L26>=$M$3,J26>=$M$3,K26>=$M$3,I26>$M$3),"Não iniciado",AND($I26<=$M$3,$K26>$M$3),"Atrasado")} -> Concluído | O26: {=_xlfn.IFS(N26="Não iniciado",0,N26="Em andamento",1,N26="Concluído",2,N26="Atrasado",3)} -> 2 | Q26: =AVERAGE(Q27,Q36,Q38) -> 1 | R26: =AVERAGE(R27,R36,R38) -> 1 | S26: =AVERAGE(S27,S36,S38) -> #REF! | T26: =AVERAGE(T27,T36,T38) -> #REF! | U26: =AVERAGE(U27,U36,U38) -> #REF! | V26: =AVERAGE(V27,V36,V38) -> #REF! | W26: =AVERAGE(W27,W36,W38) -> #REF! | X26: =AVERAGE(X27,X36,X38) -> #REF! | ... BN26: =AVERAGE(BN27,BN36,BN38) -> #REF!
B27: {=_xlfn.IFS(LEN(Tab.baseline[[#This Row],[EAP]])=1,"Nível 1",LEN(Tab.baseline[[#This Row],[EAP]])=3,"Nível 2",LEN(Tab.baseline[[#This Row],[EAP]])=5,"Nível 3",LEN(Tab.baseline[[#This Row],[EAP]])=7,"Nível 4",LEN(Tab.baseline[[#This Row],[EAP]])=9,"Nível 5",LEN(Tab.baseline[[#This Row],[EAP]])=11,"Nível 6",LEN(Tab.baseline[[#This Row],[EAP]])=11,"Nível 7")} -> Nível 4 | C27: 1.2.2.1 | D27: =$H$11 -> Arquitetura de projetos GERDAU | E27: =$H$18 -> Definição da Estratégia para Transformação dos Processos | F27: =$H$26 -> Entendimento Inicial dos Processos | G27: - | H27: Levantamento e categorização dos processos existentes | I27: =MIN(I28) -> 45706 | J27: =MAX(J28:J35) -> 45715 | K27: =MIN(K28) -> 45706 | L27: =MAX(L28:L35) -> 45722 | N27: {=_xlfn.IFS(L27<$M$3,"Concluído",AND(K27>=$M$3,I27<$M$3,L27>$M$3),"Em andamento",AND(L27>=$M$3,J27<$M$3),"Atrasado",AND(L27>=$M$3,J27>=$M$3,I27>$M$3,K27<=$M$3),"Em andamento",AND(L27>=$M$3,J27>=$M$3,I27<=$M$3,K27<=$M$3),"Em andamento",AND(K27>$M$3,I27>$M$3),"Não iniciado",AND(L27>=$M$3,J27>=$M$3,K27>=$M$3,I27<$M$3),"Atrasado",AND(L27>=$M$3,J27>=$M$3,K27>=$M$3,I27>$M$3),"Não iniciado",AND($I27<=$M$3,$K27>$M$3),"Atrasado")} -> Concluído | O27: {=_xlfn.IFS(N27="Não iniciado",0,N27="Em andamento",1,N27="Concluído",2,N27="Atrasado",3)} -> 2 | Q27: =AVERAGE(Q28:Q34) -> 1 | R27: =AVERAGE(R28:R28) -> 1 | S27: =AVERAGE(S28:S35) -> #REF! | T27: =AVERAGE(T28:T35) -> #REF! | U27: =AVERAGE(U28:U35) -> #REF! | V27: =AVERAGE(V28:V35) -> #REF! | W27: =AVERAGE(W28:W35) -> #REF! | X27: =AVERAGE(X28:X35) -> #REF! | Y27: =AVERAGE(Y28:Y35) -> #REF! | Z27: =AVERAGE(Z28:Z35) -> #REF! | ... BN27: =AVERAGE(BN28:BN35) -> #REF!
B28: {=_xlfn.IFS(LEN(Tab.baseline[[#This Row],[EAP]])=1,"Nível 1",LEN(Tab.baseline[[#This Row],[EAP]])=3,"Nível 2",LEN(Tab.baseline[[#This Row],[EAP]])=5,"Nível 3",LEN(Tab.baseline[[#This Row],[EAP]])=7,"Nível 4",LEN(Tab.baseline[[#This Row],[EAP]])=9,"Nível 5",LEN(Tab.baseline[[#This Row],[EAP]])=11,"Nível 6",LEN(Tab.baseline[[#This Row],[EAP]])=11,"Nível 7")} -> Nível 5 | C28: 1.2.2.1.1 | D28: =$H$11 -> Arquitetura de projetos GERDAU | E28: =$H$18 -> Definição da Estratégia para Transformação dos Processos | F28: =$H$26 -> Entendimento Inicial dos Processos | G28: =$H$27 -> Levantamento e categorização dos processos existentes | H28: Realizar entrevista | Pilhas de rejeitos | I28: 45706 | J28: 45708 | K28: 45706 | L28: 45708 | N28: {=_xlfn.IFS(L28<$M$3,"Concluído",AND(K28>=$M$3,I28<$M$3,L28>$M$3),"Em andamento",AND(L28>=$M$3,J28<$M$3),"Atrasado",AND(L28>=$M$3,J28>=$M$3,I28>$M$3,K28<=$M$3),"Em andamento",AND(L28>=$M$3,J28>=$M$3,I28<=$M$3,K28<=$M$3),"Em andamento",AND(K28>$M$3,I28>$M$3),"Não iniciado",AND(L28>=$M$3,J28>=$M$3,K28>=$M$3,I28<$M$3),"Atrasado",AND(L28>=$M$3,J28>=$M$3,K28>=$M$3,I28>$M$3),"Não iniciado",AND($I28<=$M$3,$K28>$M$3),"Atrasado")} -> Concluído | O28: {=_xlfn.IFS(N28="Não iniciado",0,N28="Em andamento",1,N28="Concluído",2,N28="Atrasado",3)} -> 2 | Q28: {=_xlfn.IFS(AND($I28<$N$3,$J28<$N$3),1,AND($I28<=$N$3,$J28>=$N$3),0.5,AND($I28>=$N$3,$J28>=$N$3),0)} -> 1 | R28: {=_xlfn.IFS(AND($K28<$N$3,$L28<$N$3),1,AND($K28<=$N$3,$L28>=$N$3),0.5,AND($K28>=$N$3,$L28>=$N$3),0)} -> 1 | S28: {=_xlfn.IFS(AND($K28>R$7,$L28>R$7),0,AND($K28<=R$7,$L28<=R$7),1,AND($K28<=R$7,$L28>R$7),((R$7-$K28)/($L28-$K28)))} -> #REF! | T28: {=_xlfn.IFS(AND($K28>S$7,$L28>S$7),0,AND($K28<=S$7,$L28<=S$7),1,AND($K28<=S$7,$L28>S$7),((S$7-$K28)/($L28-$K28)))} -> #REF! | U28: {=_xlfn.IFS(AND($K28>T$7,$L28>T$7),0,AND($K28<=T$7,$L28<=T$7),1,AND($K28<=T$7,$L28>T$7),((T$7-$K28)/($L28-$K28)))} -> #REF! | V28: {=_xlfn.IFS(AND($K28>U$7,$L28>U$7),0,AND($K28<=U$7,$L28<=U$7),1,AND($K28<=U$7,$L28>U$7),((U$7-$K28)/($L28-$K28)))} -> #REF! | W28: {=_xlfn.IFS(AND($K28>V$7,$L28>V$7),0,AND($K28<=V$7,$L28<=V$7),1,AND($K28<=V$7,$L28>V$7),((V$7-$K28)/($L28-$K28)))} -> #REF! | X28: {=_xlfn.IFS(AND($K28>W$7,$L28>W$7),0,AND($K28<=W$7,$L28<=W$7),1,AND($K28<=W$7,$L28>W$7),((W$7-$K28)/($L28-$K28)))} -> #REF! | Y28: {=_xlfn.IFS(AND($K28>X$7,$L28>X$7),0,AND($K28<=X$7,$L28<=X$7),1,AND($K28<=X$7,$L28>X$7),((X$7-$K28)/($L28-$K28)))} -> #REF! | Z28: {=_xlfn.IFS(AND($K28>Y$7,$L28>Y$7),0,AND($K28<=Y$7,$L28<=Y$7),1,AND($K28<=Y$7,$L28>Y$7),((Y$7-$K28)/($L28-$K28)))} -> #REF! | ... BN28: {=_xlfn.IFS(AND($K28>BM$7,$L28>BM$7),0,AND($K28<=BM$7,$L28<=BM$7),1,AND($K28<=BM$7,$L28>BM$7),((BM$7-$K28)/($L28-$K28)))} -> #REF!
B29: {=_xlfn.IFS(LEN(Tab.baseline[[#This Row],[EAP]])=1,"Nível 1",LEN(Tab.baseline[[#This Row],[EAP]])=3,"Nível 2",LEN(Tab.baseline[[#This Row],[EAP]])=5,"Nível 3",LEN(Tab.baseline[[#This Row],[EAP]])=7,"Nível 4",LEN(Tab.baseline[[#This Row],[EAP]])=9,"Nível 5",LEN(Tab.baseline[[#This Row],[EAP]])=11,"Nível 6",LEN(Tab.baseline[[#This Row],[EAP]])=11,"Nível 7")} -> Nível 5 | C29: 1.2.2.1.2 | D29: =$H$11 -> Arquitetura de projetos GERDAU | E29: =$H$18 -> Definição da Estratégia para Transformação dos Processos | F29: =$H$26 -> Entendimento Inicial dos Processos | G29: =$H$27 -> Levantamento e categorização dos processos existentes | H29: Realizar entrevista | Hidrogeologia | I29: 45714 | J29: 45714 | K29: 45714 | L29: 45714 | N29: {=_xlfn.IFS(L29<$M$3,"Concluído",AND(K29>=$M$3,I29<$M$3,L29>$M$3),"Em andamento",AND(L29>=$M$3,J29<$M$3),"Atrasado",AND(L29>=$M$3,J29>=$M$3,I29>$M$3,K29<=$M$3),"Em andamento",AND(L29>=$M$3,J29>=$M$3,I29<=$M$3,K29<=$M$3),"Em andamento",AND(K29>$M$3,I29>$M$3),"Não iniciado",AND(L29>=$M$3,J29>=$M$3,K29>=$M$3,I29<$M$3),"Atrasado",AND(L29>=$M$3,J29>=$M$3,K29>=$M$3,I29>$M$3),"Não iniciado",AND($I29<=$M$3,$K29>$M$3),"Atrasado")} -> Concluído | O29: {=_xlfn.IFS(N29="Não iniciado",0,N29="Em andamento",1,N29="Concluído",2,N29="Atrasado",3)} -> 2 | Q29: {=_xlfn.IFS(AND($I29<$N$3,$J29<$N$3),1,AND($I29<=$N$3,$J29>=$N$3),0.5,AND($I29>=$N$3,$J29>=$N$3),0)} -> 1 | R29: {=_xlfn.IFS(AND($K29<$N$3,$L29<$N$3),1,AND($K29<=$N$3,$L29>=$N$3),0.5,AND($K29>=$N$3,$L29>=$N$3),0)} -> 1 | S29: {=_xlfn.IFS(AND($K29>R$7,$L29>R$7),0,AND($K29<=R$7,$L29<=R$7),1,AND($K29<=R$7,$L29>R$7),((R$7-$K29)/($L29-$K29)))} -> #REF! | T29: {=_xlfn.IFS(AND($K29>S$7,$L29>S$7),0,AND($K29<=S$7,$L29<=S$7),1,AND($K29<=S$7,$L29>S$7),((S$7-$K29)/($L29-$K29)))} -> #REF! | U29: {=_xlfn.IFS(AND($K29>T$7,$L29>T$7),0,AND($K29<=T$7,$L29<=T$7),1,AND($K29<=T$7,$L29>T$7),((T$7-$K29)/($L29-$K29)))} -> #REF! | V29: {=_xlfn.IFS(AND($K29>U$7,$L29>U$7),0,AND($K29<=U$7,$L29<=U$7),1,AND($K29<=U$7,$L29>U$7),((U$7-$K29)/($L29-$K29)))} -> #REF! | W29: {=_xlfn.IFS(AND($K29>V$7,$L29>V$7),0,AND($K29<=V$7,$L29<=V$7),1,AND($K29<=V$7,$L29>V$7),((V$7-$K29)/($L29-$K29)))} -> #REF! | X29: {=_xlfn.IFS(AND($K29>W$7,$L29>W$7),0,AND($K29<=W$7,$L29<=W$7),1,AND($K29<=W$7,$L29>W$7),((W$7-$K29)/($L29-$K29)))} -> #REF! | Y29: {=_xlfn.IFS(AND($K29>X$7,$L29>X$7),0,AND($K29<=X$7,$L29<=X$7),1,AND($K29<=X$7,$L29>X$7),((X$7-$K29)/($L29-$K29)))} -> #REF! | Z29: {=_xlfn.IFS(AND($K29>Y$7,$L29>Y$7),0,AND($K29<=Y$7,$L29<=Y$7),1,AND($K29<=Y$7,$L29>Y$7),((Y$7-$K29)/($L29-$K29)))} -> #REF! | ... BN29: {=_xlfn.IFS(AND($K29>BM$7,$L29>BM$7),0,AND($K29<=BM$7,$L29<=BM$7),1,AND($K29<=BM$7,$L29>BM$7),((BM$7-$K29)/($L29-$K29)))} -> #REF!
B30: {=_xlfn.IFS(LEN(Tab.baseline[[#This Row],[EAP]])=1,"Nível 1",LEN(Tab.baseline[[#This Row],[EAP]])=3,"Nível 2",LEN(Tab.baseline[[#This Row],[EAP]])=5,"Nível 3",LEN(Tab.baseline[[#This Row],[EAP]])=7,"Nível 4",LEN(Tab.baseline[[#This Row],[EAP]])=9,"Nível 5",LEN(Tab.baseline[[#This Row],[EAP]])=11,"Nível 6",LEN(Tab.baseline[[#This Row],[EAP]])=11,"Nível 7")} -> Nível 5 | C30: 1.2.2.1.3 | D30: =$H$11 -> Arquitetura de projetos GERDAU | E30: =$H$18 -> Definição da Estratégia para Transformação dos Processos | F30: =$H$26 -> Entendimento Inicial dos Processos | G30: =$H$27 -> Levantamento e categorização dos processos existentes | H30: Realizar entrevista | CMG | I30: 45715 | J30: 45715 | K30: 45715 | L30: 45715 | N30: {=_xlfn.IFS(L30<$M$3,"Concluído",AND(K30>=$M$3,I30<$M$3,L30>$M$3),"Em andamento",AND(L30>=$M$3,J30<$M$3),"Atrasado",AND(L30>=$M$3,J30>=$M$3,I30>$M$3,K30<=$M$3),"Em andamento",AND(L30>=$M$3,J30>=$M$3,I30<=$M$3,K30<=$M$3),"Em andamento",AND(K30>$M$3,I30>$M$3),"Não iniciado",AND(L30>=$M$3,J30>=$M$3,K30>=$M$3,I30<$M$3),"Atrasado",AND(L30>=$M$3,J30>=$M$3,K30>=$M$3,I30>$M$3),"Não iniciado",AND($I30<=$M$3,$K30>$M$3),"Atrasado")} -> Concluído | O30: {=_xlfn.IFS(N30="Não iniciado",0,N30="Em andamento",1,N30="Concluído",2,N30="Atrasado",3)} -> 2 | Q30: {=_xlfn.IFS(AND($I30<$N$3,$J30<$N$3),1,AND($I30<=$N$3,$J30>=$N$3),0.5,AND($I30>=$N$3,$J30>=$N$3),0)} -> 1 | R30: {=_xlfn.IFS(AND($K30<$N$3,$L30<$N$3),1,AND($K30<=$N$3,$L30>=$N$3),0.5,AND($K30>=$N$3,$L30>=$N$3),0)} -> 1 | S30: {=_xlfn.IFS(AND($K30>R$7,$L30>R$7),0,AND($K30<=R$7,$L30<=R$7),1,AND($K30<=R$7,$L30>R$7),((R$7-$K30)/($L30-$K30)))} -> #REF! | T30: {=_xlfn.IFS(AND($K30>S$7,$L30>S$7),0,AND($K30<=S$7,$L30<=S$7),1,AND($K30<=S$7,$L30>S$7),((S$7-$K30)/($L30-$K30)))} -> #REF! | U30: {=_xlfn.IFS(AND($K30>T$7,$L30>T$7),0,AND($K30<=T$7,$L30<=T$7),1,AND($K30<=T$7,$L30>T$7),((T$7-$K30)/($L30-$K30)))} -> #REF! | V30: {=_xlfn.IFS(AND($K30>U$7,$L30>U$7),0,AND($K30<=U$7,$L30<=U$7),1,AND($K30<=U$7,$L30>U$7),((U$7-$K30)/($L30-$K30)))} -> #REF! | W30: {=_xlfn.IFS(AND($K30>V$7,$L30>V$7),0,AND($K30<=V$7,$L30<=V$7),1,AND($K30<=V$7,$L30>V$7),((V$7-$K30)/($L30-$K30)))} -> #REF! | X30: {=_xlfn.IFS(AND($K30>W$7,$L30>W$7),0,AND($K30<=W$7,$L30<=W$7),1,AND($K30<=W$7,$L30>W$7),((W$7-$K30)/($L30-$K30)))} -> #REF! | Y30: {=_xlfn.IFS(AND($K30>X$7,$L30>X$7),0,AND($K30<=X$7,$L30<=X$7),1,AND($K30<=X$7,$L30>X$7),((X$7-$K30)/($L30-$K30)))} -> #REF! | Z30: {=_xlfn.IFS(AND($K30>Y$7,$L30>Y$7),0,AND($K30<=Y$7,$L30<=Y$7),1,AND($K30<=Y$7,$L30>Y$7),((Y$7-$K30)/($L30-$K30)))} -> #REF! | ... BN30: {=_xlfn.IFS(AND($K30>BM$7,$L30>BM$7),0,AND($K30<=BM$7,$L30<=BM$7),1,AND($K30<=BM$7,$L30>BM$7),((BM$7-$K30)/($L30-$K30)))} -> #REF!
B31: {=_xlfn.IFS(LEN(Tab.baseline[[#This Row],[EAP]])=1,"Nível 1",LEN(Tab.baseline[[#This Row],[EAP]])=3,"Nível 2",LEN(Tab.baseline[[#This Row],[EAP]])=5,"Nível 3",LEN(Tab.baseline[[#This Row],[EAP]])=7,"Nível 4",LEN(Tab.baseline[[#This Row],[EAP]])=9,"Nível 5",LEN(Tab.baseline[[#This Row],[EAP]])=11,"Nível 6",LEN(Tab.baseline[[#This Row],[EAP]])=11,"Nível 7")} -> Nível 5 | C31: 1.2.2.1.4 | D31: =$H$11 -> Arquitetura de projetos GERDAU | E31: =$H$18 -> Definição da Estratégia para Transformação dos Processos | F31: =$H$26 -> Entendimento Inicial dos Processos | G31: =$H$27 -> Levantamento e categorização dos processos existentes | H31: Realizar entrevista | Regulatório, Governança e Controle | I31: 45713 | J31: 45713 | K31: 45713 | L31: 45713 | N31: {=_xlfn.IFS(L31<$M$3,"Concluído",AND(K31>=$M$3,I31<$M$3,L31>$M$3),"Em andamento",AND(L31>=$M$3,J31<$M$3),"Atrasado",AND(L31>=$M$3,J31>=$M$3,I31>$M$3,K31<=$M$3),"Em andamento",AND(L31>=$M$3,J31>=$M$3,I31<=$M$3,K31<=$M$3),"Em andamento",AND(K31>$M$3,I31>$M$3),"Não iniciado",AND(L31>=$M$3,J31>=$M$3,K31>=$M$3,I31<$M$3),"Atrasado",AND(L31>=$M$3,J31>=$M$3,K31>=$M$3,I31>$M$3),"Não iniciado",AND($I31<=$M$3,$K31>$M$3),"Atrasado")} -> Concluído | O31: {=_xlfn.IFS(N31="Não iniciado",0,N31="Em andamento",1,N31="Concluído",2,N31="Atrasado",3)} -> 2 | Q31: {=_xlfn.IFS(AND($I31<$N$3,$J31<$N$3),1,AND($I31<=$N$3,$J31>=$N$3),0.5,AND($I31>=$N$3,$J31>=$N$3),0)} -> 1 | R31: {=_xlfn.IFS(AND($K31<$N$3,$L31<$N$3),1,AND($K31<=$N$3,$L31>=$N$3),0.5,AND($K31>=$N$3,$L31>=$N$3),0)} -> 1 | S31: {=_xlfn.IFS(AND($K31>R$7,$L31>R$7),0,AND($K31<=R$7,$L31<=R$7),1,AND($K31<=R$7,$L31>R$7),((R$7-$K31)/($L31-$K31)))} -> #REF! | T31: {=_xlfn.IFS(AND($K31>S$7,$L31>S$7),0,AND($K31<=S$7,$L31<=S$7),1,AND($K31<=S$7,$L31>S$7),((S$7-$K31)/($L31-$K31)))} -> #REF! | U31: {=_xlfn.IFS(AND($K31>T$7,$L31>T$7),0,AND($K31<=T$7,$L31<=T$7),1,AND($K31<=T$7,$L31>T$7),((T$7-$K31)/($L31-$K31)))} -> #REF! | V31: {=_xlfn.IFS(AND($K31>U$7,$L31>U$7),0,AND($K31<=U$7,$L31<=U$7),1,AND($K31<=U$7,$L31>U$7),((U$7-$K31)/($L31-$K31)))} -> #REF! | W31: {=_xlfn.IFS(AND($K31>V$7,$L31>V$7),0,AND($K31<=V$7,$L31<=V$7),1,AND($K31<=V$7,$L31>V$7),((V$7-$K31)/($L31-$K31)))} -> #REF! | X31: {=_xlfn.IFS(AND($K31>W$7,$L31>W$7),0,AND($K31<=W$7,$L31<=W$7),1,AND($K31<=W$7,$L31>W$7),((W$7-$K31)/($L31-$K31)))} -> #REF! | Y31: {=_xlfn.IFS(AND($K31>X$7,$L31>X$7),0,AND($K31<=X$7,$L31<=X$7),1,AND($K31<=X$7,$L31>X$7),((X$7-$K31)/($L31-$K31)))} -> #REF! | Z31: {=_xlfn.IFS(AND($K31>Y$7,$L31>Y$7),0,AND($K31<=Y$7,$L31<=Y$7),1,AND($K31<=Y$7,$L31>Y$7),((Y$7-$K31)/($L31-$K31)))} -> #REF! | ... BN31: {=_xlfn.IFS(AND($K31>BM$7,$L31>BM$7),0,AND($K31<=BM$7,$L31<=BM$7),1,AND($K31<=BM$7,$L31>BM$7),((BM$7-$K31)/($L31-$K31)))} -> #REF!
B32: {=_xlfn.IFS(LEN(Tab.baseline[[#This Row],[EAP]])=1,"Nível 1",LEN(Tab.baseline[[#This Row],[EAP]])=3,"Nível 2",LEN(Tab.baseline[[#This Row],[EAP]])=5,"Nível 3",LEN(Tab.baseline[[#This Row],[EAP]])=7,"Nível 4",LEN(Tab.baseline[[#This Row],[EAP]])=9,"Nível 5",LEN(Tab.baseline[[#This Row],[EAP]])=11,"Nível 6",LEN(Tab.baseline[[#This Row],[EAP]])=11,"Nível 7")} -> Nível 5 | C32: 1.2.2.1.5 | D32: =$H$11 -> Arquitetura de projetos GERDAU | E32: =$H$18 -> Definição da Estratégia para Transformação dos Processos | F32: =$H$26 -> Entendimento Inicial dos Processos | G32: =$H$27 -> Levantamento e categorização dos processos existentes | H32: Realizar entrevista | Barragens | I32: 45715 | J32: 45715 | K32: 45715 | L32: 45715 | N32: {=_xlfn.IFS(L32<$M$3,"Concluído",AND(K32>=$M$3,I32<$M$3,L32>$M$3),"Em andamento",AND(L32>=$M$3,J32<$M$3),"Atrasado",AND(L32>=$M$3,J32>=$M$3,I32>$M$3,K32<=$M$3),"Em andamento",AND(L32>=$M$3,J32>=$M$3,I32<=$M$3,K32<=$M$3),"Em andamento",AND(K32>$M$3,I32>$M$3),"Não iniciado",AND(L32>=$M$3,J32>=$M$3,K32>=$M$3,I32<$M$3),"Atrasado",AND(L32>=$M$3,J32>=$M$3,K32>=$M$3,I32>$M$3),"Não iniciado",AND($I32<=$M$3,$K32>$M$3),"Atrasado")} -> Concluído | O32: {=_xlfn.IFS(N32="Não iniciado",0,N32="Em andamento",1,N32="Concluído",2,N32="Atrasado",3)} -> 2 | Q32: {=_xlfn.IFS(AND($I32<$N$3,$J32<$N$3),1,AND($I32<=$N$3,$J32>=$N$3),0.5,AND($I32>=$N$3,$J32>=$N$3),0)} -> 1 | R32: {=_xlfn.IFS(AND($K32<$N$3,$L32<$N$3),1,AND($K32<=$N$3,$L32>=$N$3),0.5,AND($K32>=$N$3,$L32>=$N$3),0)} -> 1 | S32: {=_xlfn.IFS(AND($K32>R$7,$L32>R$7),0,AND($K32<=R$7,$L32<=R$7),1,AND($K32<=R$7,$L32>R$7),((R$7-$K32)/($L32-$K32)))} -> #REF! | T32: {=_xlfn.IFS(AND($K32>S$7,$L32>S$7),0,AND($K32<=S$7,$L32<=S$7),1,AND($K32<=S$7,$L32>S$7),((S$7-$K32)/($L32-$K32)))} -> #REF! | U32: {=_xlfn.IFS(AND($K32>T$7,$L32>T$7),0,AND($K32<=T$7,$L32<=T$7),1,AND($K32<=T$7,$L32>T$7),((T$7-$K32)/($L32-$K32)))} -> #REF! | V32: {=_xlfn.IFS(AND($K32>U$7,$L32>U$7),0,AND($K32<=U$7,$L32<=U$7),1,AND($K32<=U$7,$L32>U$7),((U$7-$K32)/($L32-$K32)))} -> #REF! | W32: {=_xlfn.IFS(AND($K32>V$7,$L32>V$7),0,AND($K32<=V$7,$L32<=V$7),1,AND($K32<=V$7,$L32>V$7),((V$7-$K32)/($L32-$K32)))} -> #REF! | X32: {=_xlfn.IFS(AND($K32>W$7,$L32>W$7),0,AND($K32<=W$7,$L32<=W$7),1,AND($K32<=W$7,$L32>W$7),((W$7-$K32)/($L32-$K32)))} -> #REF! | Y32: {=_xlfn.IFS(AND($K32>X$7,$L32>X$7),0,AND($K32<=X$7,$L32<=X$7),1,AND($K32<=X$7,$L32>X$7),((X$7-$K32)/($L32-$K32)))} -> #REF! | Z32: {=_xlfn.IFS(AND($K32>Y$7,$L32>Y$7),0,AND($K32<=Y$7,$L32<=Y$7),1,AND($K32<=Y$7,$L32>Y$7),((Y$7-$K32)/($L32-$K32)))} -> #REF! | ... BN32: {=_xlfn.IFS(AND($K32>BM$7,$L32>BM$7),0,AND($K32<=BM$7,$L32<=BM$7),1,AND($K32<=BM$7,$L32>BM$7),((BM$7-$K32)/($L32-$K32)))} -> #REF!
B33: {=_xlfn.IFS(LEN(Tab.baseline[[#This Row],[EAP]])=1,"Nível 1",LEN(Tab.baseline[[#This Row],[EAP]])=3,"Nível 2",LEN(Tab.baseline[[#This Row],[EAP]])=5,"Nível 3",LEN(Tab.baseline[[#This Row],[EAP]])=7,"Nível 4",LEN(Tab.baseline[[#This Row],[EAP]])=9,"Nível 5",LEN(Tab.baseline[[#This Row],[EAP]])=11,"Nível 6",LEN(Tab.baseline[[#This Row],[EAP]])=11,"Nível 7")} -> Nível 5 | C33: 1.2.2.1.6 | D33: =$H$11 -> Arquitetura de projetos GERDAU | E33: =$H$18 -> Definição da Estratégia para Transformação dos Processos | F33: =$H$26 -> Entendimento Inicial dos Processos | G33: =$H$27 -> Levantamento e categorização dos processos existentes | H33: Realizar entrevista | Financeiro | I33: 45713 | J33: 45713 | K33: 45713 | L33: 45713 | N33: {=_xlfn.IFS(L33<$M$3,"Concluído",AND(K33>=$M$3,I33<$M$3,L33>$M$3),"Em andamento",AND(L33>=$M$3,J33<$M$3),"Atrasado",AND(L33>=$M$3,J33>=$M$3,I33>$M$3,K33<=$M$3),"Em andamento",AND(L33>=$M$3,J33>=$M$3,I33<=$M$3,K33<=$M$3),"Em andamento",AND(K33>$M$3,I33>$M$3),"Não iniciado",AND(L33>=$M$3,J33>=$M$3,K33>=$M$3,I33<$M$3),"Atrasado",AND(L33>=$M$3,J33>=$M$3,K33>=$M$3,I33>$M$3),"Não iniciado",AND($I33<=$M$3,$K33>$M$3),"Atrasado")} -> Concluído | O33: {=_xlfn.IFS(N33="Não iniciado",0,N33="Em andamento",1,N33="Concluído",2,N33="Atrasado",3)} -> 2 | Q33: {=_xlfn.IFS(AND($I33<$N$3,$J33<$N$3),1,AND($I33<=$N$3,$J33>=$N$3),0.5,AND($I33>=$N$3,$J33>=$N$3),0)} -> 1 | R33: {=_xlfn.IFS(AND($K33<$N$3,$L33<$N$3),1,AND($K33<=$N$3,$L33>=$N$3),0.5,AND($K33>=$N$3,$L33>=$N$3),0)} -> 1 | S33: {=_xlfn.IFS(AND($K33>R$7,$L33>R$7),0,AND($K33<=R$7,$L33<=R$7),1,AND($K33<=R$7,$L33>R$7),((R$7-$K33)/($L33-$K33)))} -> #REF! | T33: {=_xlfn.IFS(AND($K33>S$7,$L33>S$7),0,AND($K33<=S$7,$L33<=S$7),1,AND($K33<=S$7,$L33>S$7),((S$7-$K33)/($L33-$K33)))} -> #REF! | U33: {=_xlfn.IFS(AND($K33>T$7,$L33>T$7),0,AND($K33<=T$7,$L33<=T$7),1,AND($K33<=T$7,$L33>T$7),((T$7-$K33)/($L33-$K33)))} -> #REF! | V33: {=_xlfn.IFS(AND($K33>U$7,$L33>U$7),0,AND($K33<=U$7,$L33<=U$7),1,AND($K33<=U$7,$L33>U$7),((U$7-$K33)/($L33-$K33)))} -> #REF! | W33: {=_xlfn.IFS(AND($K33>V$7,$L33>V$7),0,AND($K33<=V$7,$L33<=V$7),1,AND($K33<=V$7,$L33>V$7),((V$7-$K33)/($L33-$K33)))} -> #REF! | X33: {=_xlfn.IFS(AND($K33>W$7,$L33>W$7),0,AND($K33<=W$7,$L33<=W$7),1,AND($K33<=W$7,$L33>W$7),((W$7-$K33)/($L33-$K33)))} -> #REF! | Y33: {=_xlfn.IFS(AND($K33>X$7,$L33>X$7),0,AND($K33<=X$7,$L33<=X$7),1,AND($K33<=X$7,$L33>X$7),((X$7-$K33)/($L33-$K33)))} -> #REF! | Z33: {=_xlfn.IFS(AND($K33>Y$7,$L33>Y$7),0,AND($K33<=Y$7,$L33<=Y$7),1,AND($K33<=Y$7,$L33>Y$7),((Y$7-$K33)/($L33-$K33)))} -> #REF! | ... BN33: {=_xlfn.IFS(AND($K33>BM$7,$L33>BM$7),0,AND($K33<=BM$7,$L33<=BM$7),1,AND($K33<=BM$7,$L33>BM$7),((BM$7-$K33)/($L33-$K33)))} -> #REF!
B34: {=_xlfn.IFS(LEN(Tab.baseline[[#This Row],[EAP]])=1,"Nível 1",LEN(Tab.baseline[[#This Row],[EAP]])=3,"Nível 2",LEN(Tab.baseline[[#This Row],[EAP]])=5,"Nível 3",LEN(Tab.baseline[[#This Row],[EAP]])=7,"Nível 4",LEN(Tab.baseline[[#This Row],[EAP]])=9,"Nível 5",LEN(Tab.baseline[[#This Row],[EAP]])=11,"Nível 6",LEN(Tab.baseline[[#This Row],[EAP]])=11,"Nível 7")} -> Nível 5 | C34: 1.2.2.1.7 | D34: =$H$11 -> Arquitetura de projetos GERDAU | E34: =$H$18 -> Definição da Estratégia para Transformação dos Processos | F34: =$H$26 -> Entendimento Inicial dos Processos | G34: =$H$27 -> Levantamento e categorização dos processos existentes | H34: Realizar entrevista | Pilhas de estéril | I34: 45715 | J34: 45715 | K34: 45715 | L34: 45715 | N34: {=_xlfn.IFS(L34<$M$3,"Concluído",AND(K34>=$M$3,I34<$M$3,L34>$M$3),"Em andamento",AND(L34>=$M$3,J34<$M$3),"Atrasado",AND(L34>=$M$3,J34>=$M$3,I34>$M$3,K34<=$M$3),"Em andamento",AND(L34>=$M$3,J34>=$M$3,I34<=$M$3,K34<=$M$3),"Em andamento",AND(K34>$M$3,I34>$M$3),"Não iniciado",AND(L34>=$M$3,J34>=$M$3,K34>=$M$3,I34<$M$3),"Atrasado",AND(L34>=$M$3,J34>=$M$3,K34>=$M$3,I34>$M$3),"Não iniciado",AND($I34<=$M$3,$K34>$M$3),"Atrasado")} -> Concluído | O34: {=_xlfn.IFS(N34="Não iniciado",0,N34="Em andamento",1,N34="Concluído",2,N34="Atrasado",3)} -> 2 | Q34: {=_xlfn.IFS(AND($I34<$N$3,$J34<$N$3),1,AND($I34<=$N$3,$J34>=$N$3),0.5,AND($I34>=$N$3,$J34>=$N$3),0)} -> 1 | R34: {=_xlfn.IFS(AND($K34<$N$3,$L34<$N$3),1,AND($K34<=$N$3,$L34>=$N$3),0.5,AND($K34>=$N$3,$L34>=$N$3),0)} -> 1 | S34: {=_xlfn.IFS(AND($K34>R$7,$L34>R$7),0,AND($K34<=R$7,$L34<=R$7),1,AND($K34<=R$7,$L34>R$7),((R$7-$K34)/($L34-$K34)))} -> #REF! | T34: {=_xlfn.IFS(AND($K34>S$7,$L34>S$7),0,AND($K34<=S$7,$L34<=S$7),1,AND($K34<=S$7,$L34>S$7),((S$7-$K34)/($L34-$K34)))} -> #REF! | U34: {=_xlfn.IFS(AND($K34>T$7,$L34>T$7),0,AND($K34<=T$7,$L34<=T$7),1,AND($K34<=T$7,$L34>T$7),((T$7-$K34)/($L34-$K34)))} -> #REF! | V34: {=_xlfn.IFS(AND($K34>U$7,$L34>U$7),0,AND($K34<=U$7,$L34<=U$7),1,AND($K34<=U$7,$L34>U$7),((U$7-$K34)/($L34-$K34)))} -> #REF! | W34: {=_xlfn.IFS(AND($K34>V$7,$L34>V$7),0,AND($K34<=V$7,$L34<=V$7),1,AND($K34<=V$7,$L34>V$7),((V$7-$K34)/($L34-$K34)))} -> #REF! | X34: {=_xlfn.IFS(AND($K34>W$7,$L34>W$7),0,AND($K34<=W$7,$L34<=W$7),1,AND($K34<=W$7,$L34>W$7),((W$7-$K34)/($L34-$K34)))} -> #REF! | Y34: {=_xlfn.IFS(AND($K34>X$7,$L34>X$7),0,AND($K34<=X$7,$L34<=X$7),1,AND($K34<=X$7,$L34>X$7),((X$7-$K34)/($L34-$K34)))} -> #REF! | Z34: {=_xlfn.IFS(AND($K34>Y$7,$L34>Y$7),0,AND($K34<=Y$7,$L34<=Y$7),1,AND($K34<=Y$7,$L34>Y$7),((Y$7-$K34)/($L34-$K34)))} -> #REF! | ... BN34: {=_xlfn.IFS(AND($K34>BM$7,$L34>BM$7),0,AND($K34<=BM$7,$L34<=BM$7),1,AND($K34<=BM$7,$L34>BM$7),((BM$7-$K34)/($L34-$K34)))} -> #REF!
B35: {=_xlfn.IFS(LEN(Tab.baseline[[#This Row],[EAP]])=1,"Nível 1",LEN(Tab.baseline[[#This Row],[EAP]])=3,"Nível 2",LEN(Tab.baseline[[#This Row],[EAP]])=5,"Nível 3",LEN(Tab.baseline[[#This Row],[EAP]])=7,"Nível 4",LEN(Tab.baseline[[#This Row],[EAP]])=9,"Nível 5",LEN(Tab.baseline[[#This Row],[EAP]])=11,"Nível 6",LEN(Tab.baseline[[#This Row],[EAP]])=11,"Nível 7")} -> Nível 5 | C35: 1.2.2.1.8 | E35: =$H$18 -> Definição da Estratégia para Transformação dos Processos | F35: =$H$26 -> Entendimento Inicial dos Processos | G35: =$H$27 -> Levantamento e categorização dos processos existentes | H35: Realizar entrevista | Cavas | I35: 45715 | J35: 45715 | K35: 45720 | L35: 45722 | N35: {=_xlfn.IFS(L35<$M$3,"Concluído",AND(K35>=$M$3,I35<$M$3,L35>$M$3),"Em andamento",AND(L35>=$M$3,J35<$M$3),"Atrasado",AND(L35>=$M$3,J35>=$M$3,I35>$M$3,K35<=$M$3),"Em andamento",AND(L35>=$M$3,J35>=$M$3,I35<=$M$3,K35<=$M$3),"Em andamento",AND(K35>$M$3,I35>$M$3),"Não iniciado",AND(L35>=$M$3,J35>=$M$3,K35>=$M$3,I35<$M$3),"Atrasado",AND(L35>=$M$3,J35>=$M$3,K35>=$M$3,I35>$M$3),"Não iniciado",AND($I35<=$M$3,$K35>$M$3),"Atrasado")} -> Concluído | O35: {=_xlfn.IFS(N35="Não iniciado",0,N35="Em andamento",1,N35="Concluído",2,N35="Atrasado",3)} -> 2 | Q35: {=_xlfn.IFS(AND($I35<$N$3,$J35<$N$3),1,AND($I35<=$N$3,$J35>=$N$3),0.5,AND($I35>=$N$3,$J35>=$N$3),0)} -> 1 | R35: {=_xlfn.IFS(AND($K35<$N$3,$L35<$N$3),1,AND($K35<=$N$3,$L35>=$N$3),0.5,AND($K35>=$N$3,$L35>=$N$3),0)} -> 1 | S35: {=_xlfn.IFS(AND($K35>R$7,$L35>R$7),0,AND($K35<=R$7,$L35<=R$7),1,AND($K35<=R$7,$L35>R$7),((R$7-$K35)/($L35-$K35)))} -> #REF! | T35: {=_xlfn.IFS(AND($K35>S$7,$L35>S$7),0,AND($K35<=S$7,$L35<=S$7),1,AND($K35<=S$7,$L35>S$7),((S$7-$K35)/($L35-$K35)))} -> #REF! | U35: {=_xlfn.IFS(AND($K35>T$7,$L35>T$7),0,AND($K35<=T$7,$L35<=T$7),1,AND($K35<=T$7,$L35>T$7),((T$7-$K35)/($L35-$K35)))} -> #REF! | V35: {=_xlfn.IFS(AND($K35>U$7,$L35>U$7),0,AND($K35<=U$7,$L35<=U$7),1,AND($K35<=U$7,$L35>U$7),((U$7-$K35)/($L35-$K35)))} -> #REF! | W35: {=_xlfn.IFS(AND($K35>V$7,$L35>V$7),0,AND($K35<=V$7,$L35<=V$7),1,AND($K35<=V$7,$L35>V$7),((V$7-$K35)/($L35-$K35)))} -> #REF! | X35: {=_xlfn.IFS(AND($K35>W$7,$L35>W$7),0,AND($K35<=W$7,$L35<=W$7),1,AND($K35<=W$7,$L35>W$7),((W$7-$K35)/($L35-$K35)))} -> #REF! | Y35: {=_xlfn.IFS(AND($K35>X$7,$L35>X$7),0,AND($K35<=X$7,$L35<=X$7),1,AND($K35<=X$7,$L35>X$7),((X$7-$K35)/($L35-$K35)))} -> #REF! | Z35: {=_xlfn.IFS(AND($K35>Y$7,$L35>Y$7),0,AND($K35<=Y$7,$L35<=Y$7),1,AND($K35<=Y$7,$L35>Y$7),((Y$7-$K35)/($L35-$K35)))} -> #REF! | ... BN35: {=_xlfn.IFS(AND($K35>BM$7,$L35>BM$7),0,AND($K35<=BM$7,$L35<=BM$7),1,AND($K35<=BM$7,$L35>BM$7),((BM$7-$K35)/($L35-$K35)))} -> #REF!
B36: {=_xlfn.IFS(LEN(Tab.baseline[[#This Row],[EAP]])=1,"Nível 1",LEN(Tab.baseline[[#This Row],[EAP]])=3,"Nível 2",LEN(Tab.baseline[[#This Row],[EAP]])=5,"Nível 3",LEN(Tab.baseline[[#This Row],[EAP]])=7,"Nível 4",LEN(Tab.baseline[[#This Row],[EAP]])=9,"Nível 5",LEN(Tab.baseline[[#This Row],[EAP]])=11,"Nível 6",LEN(Tab.baseline[[#This Row],[EAP]])=11,"Nível 7")} -> Nível 4 | C36: 1.2.2.2 | D36: =$H$11 -> Arquitetura de projetos GERDAU | E36: =$H$18 -> Definição da Estratégia para Transformação dos Processos | F36: =$H$26 -> Entendimento Inicial dos Processos | G36: Estruturação do Questionário para Diagnóstico de PAEBM | H36: Identificação de Ferramentas e Sistemas | I36: =MIN(I37) -> 45705 | J36: =MAX(J37) -> 45715 | K36: =MIN(K37) -> 45705 | L36: =MAX(L37) -> 45722 | N36: {=_xlfn.IFS(L36<$M$3,"Concluído",AND(K36>=$M$3,I36<$M$3,L36>$M$3),"Em andamento",AND(L36>=$M$3,J36<$M$3),"Atrasado",AND(L36>=$M$3,J36>=$M$3,I36>$M$3,K36<=$M$3),"Em andamento",AND(L36>=$M$3,J36>=$M$3,I36<=$M$3,K36<=$M$3),"Em andamento",AND(K36>$M$3,I36>$M$3),"Não iniciado",AND(L36>=$M$3,J36>=$M$3,K36>=$M$3,I36<$M$3),"Atrasado",AND(L36>=$M$3,J36>=$M$3,K36>=$M$3,I36>$M$3),"Não iniciado",AND($I36<=$M$3,$K36>$M$3),"Atrasado")} -> Concluído | O36: {=_xlfn.IFS(N36="Não iniciado",0,N36="Em andamento",1,N36="Concluído",2,N36="Atrasado",3)} -> 2 | Q36: {=_xlfn.IFS(AND($I36<$M$3,$J36<$M$3),1,AND($I36<$M$3,$J36>=$M$3),0.5,AND($I36>=$M$3,$J36>=$M$3),0)} -> 1 | R36: {=_xlfn.IFS(AND($I36<$M$3,$J36<$M$3),1,AND($I36<$M$3,$J36>=$M$3),0.5,AND($I36>=$M$3,$J36>=$M$3),0)} -> 1 | S36: {=_xlfn.IFS(AND($K36>R$7,$L36>R$7),0,AND($K36<=R$7,$L36<=R$7),1,AND($K36<=R$7,$L36>R$7),((R$7-$K36)/($L36-$K36)))} -> #REF! | T36: {=_xlfn.IFS(AND($K36>S$7,$L36>S$7),0,AND($K36<=S$7,$L36<=S$7),1,AND($K36<=S$7,$L36>S$7),((S$7-$K36)/($L36-$K36)))} -> #REF! | U36: {=_xlfn.IFS(AND($K36>T$7,$L36>T$7),0,AND($K36<=T$7,$L36<=T$7),1,AND($K36<=T$7,$L36>T$7),((T$7-$K36)/($L36-$K36)))} -> #REF! | V36: {=_xlfn.IFS(AND($K36>U$7,$L36>U$7),0,AND($K36<=U$7,$L36<=U$7),1,AND($K36<=U$7,$L36>U$7),((U$7-$K36)/($L36-$K36)))} -> #REF! | W36: {=_xlfn.IFS(AND($K36>V$7,$L36>V$7),0,AND($K36<=V$7,$L36<=V$7),1,AND($K36<=V$7,$L36>V$7),((V$7-$K36)/($L36-$K36)))} -> #REF! | X36: {=_xlfn.IFS(AND($K36>W$7,$L36>W$7),0,AND($K36<=W$7,$L36<=W$7),1,AND($K36<=W$7,$L36>W$7),((W$7-$K36)/($L36-$K36)))} -> #REF! | Y36: {=_xlfn.IFS(AND($K36>X$7,$L36>X$7),0,AND($K36<=X$7,$L36<=X$7),1,AND($K36<=X$7,$L36>X$7),((X$7-$K36)/($L36-$K36)))} -> #REF! | Z36: {=_xlfn.IFS(AND($K36>Y$7,$L36>Y$7),0,AND($K36<=Y$7,$L36<=Y$7),1,AND($K36<=Y$7,$L36>Y$7),((Y$7-$K36)/($L36-$K36)))} -> #REF! | ... BN36: {=_xlfn.IFS(AND($K36>BM$7,$L36>BM$7),0,AND($K36<=BM$7,$L36<=BM$7),1,AND($K36<=BM$7,$L36>BM$7),((BM$7-$K36)/($L36-$K36)))} -> #REF!
